Workbook

Sheet URL_ALL
A1: ID | B1: Imagen Original | C1: Imagen Renombrada | D1: Name | E1: Sector | F1: Sensor | G1: Proyecto | H1: FechaAdqui | I1: FechaCarga | J1: Estado | K1: URL | L1: PAIS | M1: COMPAÑÍA | N1: TIPO | O1: Tipo 2 | P1: DIA | Q1: MES | R1: AÑO | S1: Carpeta | T1: Zorder | U1: Mosaic Dataset | V1: Nombre Concatenado | W1: Nombre Sector | X1: Verificacion | Y1: Correlativo Vuelo | Z1: NombreVuelo
A2: 1 | B2: 20250108_EB1-Orthomosaic.tiff | C2: =CONCATENATE(L2,"_",M2,"_",G2,"_",N2,"_",O2,"_",R2,"_",Q2,"_",P2,"_",E2,".tiff") -> CL_MLP_PAO_IF_Ortho_25_01_08_EB1.tiff | D2: =CONCATENATE(L2,"_",M2,"_",G2,"_",N2,"_",O2,"_",R2,"_",Q2,"_",P2,"_",E2) -> CL_MLP_PAO_IF_Ortho_25_01_08_EB1 | E2: EB1 | F2: DJI MATRICE 350 RTK | G2: PAO | H2: 45665.167 | I2: 45868 | J2: Activo | K2: =CONCATENATE("https://sig.aminerals.cl/imgdyn/rest/services/CL_MLP_PAO/",U2,"/","ImageServer/file?id=.\",S2,"\",R2,"_",Q2,"_",P2,"\",C2,"&rasterId=") -> https://sig.aminerals.cl/imgdyn/rest/services/CL_MLP_PAO/CL_MLP_PAO_IF_Ortho_ALL/ImageServer/file?id=.\Puerto_Punta_Chungo_Drone\25_01_08\CL_MLP_PAO_IF_Ortho_25_01_08_EB1.tiff&rasterId= | L2: CL | M2: MLP | N2: IF | O2: Ortho | P2: =TEXT(H2,"dd") -> 08 | Q2: =TEXT(H2,"MM") -> 01 | R2: =TEXT(H2,"YY") -> 25 | S2: Puerto_Punta_Chungo_Drone | T2: 1 | U2: CL_MLP_PAO_IF_Ortho_ALL | V2: =RIGHT(D2,LEN(D2)-29) -> EB1 | W2: =E2 -> EB1 | X2: =V2=W2 -> TRUE | Y2: =VLOOKUP(D2,'Orden de Imagen'!$A$1:D142,4,FALSE()) -> 001 | Z2: =CONCATENATE(Y2,"_",R2,"_",Q2,"_",P2,"_",E2) -> 001_25_01_08_EB1
A3: 2 | B3: 20250226_Area1_Cuncumen-D835-Orthomosaic.tiff | C3: CL_MLP_PAO_IF_Ortho_25_02_26_Area1_Cuncumen-D835.tiff | D3: =CONCATENATE(L3,"_",M3,"_",G3,"_",N3,"_",O3,"_",R3,"_",Q3,"_",P3,"_",E3) -> CL_MLP_PAO_IF_Ortho_25_02_26_Area1_Cuncumen-D835 | E3: Area1_Cuncumen-D835 | F3: DJI MATRICE 350 RTK | G3: PAO | H3: 45714.167 | I3: 45868 | J3: Activo | K3: =CONCATENATE("https://sig.aminerals.cl/imgdyn/rest/services/CL_MLP_PAO/",U3,"/","ImageServer/file?id=.\",S3,"\",R3,"_",Q3,"_",P3,"\",C3,"&rasterId=") -> https://sig.aminerals.cl/imgdyn/rest/services/CL_MLP_PAO/CL_MLP_PAO_IF_Ortho_ALL/ImageServer/file?id=.\Chacay_El_Mauro_Drone\25_02_26\CL_MLP_PAO_IF_Ortho_25_02_26_Area1_Cuncumen-D835.tiff&rasterId= | L3: CL | M3: MLP | N3: IF | O3: Ortho | P3: =TEXT(H3,"dd") -> 26 | Q3: =TEXT(H3,"MM") -> 02 | R3: =TEXT(H3,"YY") -> 25 | S3: Chacay_El_Mauro_Drone | T3: 1 | U3: CL_MLP_PAO_IF_Ortho_ALL | V3: =RIGHT(D3,LEN(D3)-29) -> Area1_Cuncumen-D835 | W3: Area1_Cuncumen-D835 | X3: =V3=W3 -> TRUE | Y3: =VLOOKUP(D3,'Orden de Imagen'!$A$1:D143,4,FALSE()) -> #N/A | Z3: =CONCATENATE(Y3,"_",R3,"_",Q3,"_",P3,"_",E3) -> #N/A
A4: 3 | B4: 20250226_Area2_Cuncumen-D835-Orthomosaic.tiff | C4: CL_MLP_PAO_IF_Ortho_25_02_26_Area2_Cuncumen-D835.tiff | D4: =CONCATENATE(L4,"_",M4,"_",G4,"_",N4,"_",O4,"_",R4,"_",Q4,"_",P4,"_",E4) -> CL_MLP_PAO_IF_Ortho_25_02_26_Area2_Cuncumen-D835 | E4: Area2_Cuncumen-D835 | F4: DJI MATRICE 350 RTK | G4: PAO | H4: 45714.167 | I4: 45869 | J4: Activo | K4: =CONCATENATE("https://sig.aminerals.cl/imgdyn/rest/services/CL_MLP_PAO/",U4,"/","ImageServer/file?id=.\",S4,"\",R4,"_",Q4,"_",P4,"\",C4,"&rasterId=") -> https://sig.aminerals.cl/imgdyn/rest/services/CL_MLP_PAO/CL_MLP_PAO_IF_Ortho_ALL/ImageServer/file?id=.\Chacay_El_Mauro_Drone\25_02_26\CL_MLP_PAO_IF_Ortho_25_02_26_Area2_Cuncumen-D835.tiff&rasterId= | L4: CL | M4: MLP | N4: IF | O4: Ortho | P4: =TEXT(H4,"dd") -> 26 | Q4: =TEXT(H4,"MM") -> 02 | R4: =TEXT(H4,"YY") -> 25 | S4: Chacay_El_Mauro_Drone | T4: 1 | U4: CL_MLP_PAO_IF_Ortho_ALL | V4: =RIGHT(D4,LEN(D4)-29) -> Area2_Cuncumen-D835 | W4: =E4 -> Area2_Cuncumen-D835 | X4: =V4=W4 -> TRUE | Y4: =VLOOKUP(D4,'Orden de Imagen'!$A$1:D144,4,FALSE()) -> #N/A | Z4: =CONCATENATE(Y4,"_",R4,"_",Q4,"_",P4,"_",E4) -> #N/A
A5: 4 | B5: 20250226_RutaD835.tif | C5: CL_MLP_PAO_IF_Ortho_25_02_26_RutaD835.tiff | D5: =CONCATENATE(L5,"_",M5,"_",G5,"_",N5,"_",O5,"_",R5,"_",Q5,"_",P5,"_",E5) -> CL_MLP_PAO_IF_Ortho_25_02_26_RutaD835 | E5: RutaD835 | F5: DJI MATRICE 350 RTK | G5: PAO | H5: 45714.167 | I5: 45870 | J5: Activo | K5: =CONCATENATE("https://sig.aminerals.cl/imgdyn/rest/services/CL_MLP_PAO/",U5,"/","ImageServer/file?id=.\",S5,"\",R5,"_",Q5,"_",P5,"\",C5,"&rasterId=") -> https://sig.aminerals.cl/imgdyn/rest/services/CL_MLP_PAO/CL_MLP_PAO_IF_Ortho_ALL/ImageServer/file?id=.\Chacay_El_Mauro_Drone\25_02_26\CL_MLP_PAO_IF_Ortho_25_02_26_RutaD835.tiff&rasterId= | L5: CL | M5: MLP | N5: IF | O5: Ortho | P5: =TEXT(H5,"dd") -> 26 | Q5: =TEXT(H5,"MM") -> 02 | R5: =TEXT(H5,"YY") -> 25 | S5: Chacay_El_Mauro_Drone | T5: 1 | U5: CL_MLP_PAO_IF_Ortho_ALL | V5: =RIGHT(D5,LEN(D5)-29) -> RutaD835 | W5: =E5 -> RutaD835 | X5: =V5=W5 -> TRUE | Y5: =VLOOKUP(D5,'Orden de Imagen'!$A$1:D145,4,FALSE()) -> 002 | Z5: =CONCATENATE(Y5,"_",R5,"_",Q5,"_",P5,"_",E5) -> 002_25_02_26_RutaD835
A6: 5 | B6: 20250310_NSTC_116a118.tif | C6: CL_MLP_PAO_IF_Ortho_25_03_10_NSTC_116a118.tiff | D6: =CONCATENATE(L6,"_",M6,"_",G6,"_",N6,"_",O6,"_",R6,"_",Q6,"_",P6,"_",E6) -> CL_MLP_PAO_IF_Ortho_25_03_10_NSTC_116a118 | E6: NSTC_116a118 | F6: DJI MATRICE 350 RTK | G6: PAO | H6: 45726.167 | I6: 45870 | J6: Activo | K6: =CONCATENATE("https://sig.aminerals.cl/imgdyn/rest/services/CL_MLP_PAO/",U6,"/","ImageServer/file?id=.\",S6,"\",R6,"_",Q6,"_",P6,"\",C6,"&rasterId=") -> https://sig.aminerals.cl/imgdyn/rest/services/CL_MLP_PAO/CL_MLP_PAO_IF_Ortho_ALL/ImageServer/file?id=.\El_Mauro_Puerto_Punta_Chungo_Drone\25_03_10\CL_MLP_PAO_IF_Ortho_25_03_10_NSTC_116a118.tiff&rasterId= | L6: CL | M6: MLP | N6: IF | O6: Ortho | P6: =TEXT(H6,"dd") -> 10 | Q6: =TEXT(H6,"MM") -> 03 | R6: =TEXT(H6,"YY") -> 25 | S6: El_Mauro_Puerto_Punta_Chungo_Drone | T6: 1 | U6: CL_MLP_PAO_IF_Ortho_ALL | V6: =RIGHT(D6,LEN(D6)-29) -> NSTC_116a118 | W6: =E6 -> NSTC_116a118 | X6: =V6=W6 -> TRUE | Y6: =VLOOKUP(D6,'Orden de Imagen'!$A$1:D146,4,FALSE()) -> 003 | Z6: =CONCATENATE(Y6,"_",R6,"_",Q6,"_",P6,"_",E6) -> 003_25_03_10_NSTC_116a118
A7: 6 | B7: 20250310_NSTC_118a120.tif | C7: CL_MLP_PAO_IF_Ortho_25_03_10_NSTC_118a120.tiff | D7: =CONCATENATE(L7,"_",M7,"_",G7,"_",N7,"_",O7,"_",R7,"_",Q7,"_",P7,"_",E7) -> CL_MLP_PAO_IF_Ortho_25_03_10_NSTC_118a120 | E7: NSTC_118a120 | F7: DJI MATRICE 350 RTK | G7: PAO | H7: 45726.167 | I7: 45870 | J7: Activo | K7: =CONCATENATE("https://sig.aminerals.cl/imgdyn/rest/services/CL_MLP_PAO/",U7,"/","ImageServer/file?id=.\",S7,"\",R7,"_",Q7,"_",P7,"\",C7,"&rasterId=") -> https://sig.aminerals.cl/imgdyn/rest/services/CL_MLP_PAO/CL_MLP_PAO_IF_Ortho_ALL/ImageServer/file?id=.\El_Mauro_Puerto_Punta_Chungo_Drone\25_03_10\CL_MLP_PAO_IF_Ortho_25_03_10_NSTC_118a120.tiff&rasterId= | L7: CL | M7: MLP | N7: IF | O7: Ortho | P7: =TEXT(H7,"dd") -> 10 | Q7: =TEXT(H7,"MM") -> 03 | R7: =TEXT(H7,"YY") -> 25 | S7: El_Mauro_Puerto_Punta_Chungo_Drone | T7: 1 | U7: CL_MLP_PAO_IF_Ortho_ALL | V7: =RIGHT(D7,LEN(D7)-29) -> NSTC_118a120 | W7: =E7 -> NSTC_118a120 | X7: =V7=W7 -> TRUE | Y7: =VLOOKUP(D7,'Orden de Imagen'!$A$1:D147,4,FALSE()) -> 004 | Z7: =CONCATENATE(Y7,"_",R7,"_",Q7,"_",P7,"_",E7) -> 004_25_03_10_NSTC_118a120
A8: 7 | B8: 20250312_SRA2.tif | C8: =CONCATENATE(L8,"_",M8,"_",G8,"_",N8,"_",O8,"_",R8,"_",Q8,"_",P8,"_",E8,".tif") -> CL_MLP_PAO_IF_Ortho_25_03_12_SRA2.tif | D8: =CONCATENATE(L8,"_",M8,"_",G8,"_",N8,"_",O8,"_",R8,"_",Q8,"_",P8,"_",E8) -> CL_MLP_PAO_IF_Ortho_25_03_12_SRA2 | E8: SRA2 | F8: DJI MATRICE 350 RTK | G8: PAO | H8: 45728.167 | I8: 45797 | J8: Activo | K8: =CONCATENATE("https://sig.aminerals.cl/imgdyn/rest/services/CL_MLP_PAO/",U8,"/","ImageServer/file?id=.\",S8,"\",R8,"_",Q8,"_",P8,"\",C8,"&rasterId=") -> https://sig.aminerals.cl/imgdyn/rest/services/CL_MLP_PAO/CL_MLP_PAO_IF_Ortho_ALL/ImageServer/file?id=.\Chacay_Drone\25_03_12\CL_MLP_PAO_IF_Ortho_25_03_12_SRA2.tif&rasterId= | L8: CL | M8: MLP | N8: IF | O8: Ortho | P8: =TEXT(H8,"dd") -> 12 | Q8: =TEXT(H8,"MM") -> 03 | R8: =TEXT(H8,"YY") -> 25 | S8: Chacay_Drone | T8: 1 | U8: CL_MLP_PAO_IF_Ortho_ALL | V8: =RIGHT(D8,LEN(D8)-29) -> SRA2 | W8: =E8 -> SRA2 | X8: =V8=W8 -> TRUE | Y8: =VLOOKUP(D8,'Orden de Imagen'!$A$1:D148,4,FALSE()) -> 005 | Z8: =CONCATENATE(Y8,"_",R8,"_",Q8,"_",P8,"_",E8) -> 005_25_03_12_SRA2
A9: 8 | B9: 20250317_NSTC_120a121.tif | C9: CL_MLP_PAO_IF_Ortho_25_03_17_NSTC_Km_120_a_121.tif | D9: =CONCATENATE(L9,"_",M9,"_",G9,"_",N9,"_",O9,"_",R9,"_",Q9,"_",P9,"_",E9) -> CL_MLP_PAO_IF_Ortho_25_03_17_NSTC_Km_120_a_121 | E9: NSTC_Km_120_a_121 | F9: DJI MATRICE 350 RTK | G9: PAO | H9: 45733.167 | I9: 45870 | J9: Activo | K9: =CONCATENATE("https://sig.aminerals.cl/imgdyn/rest/services/CL_MLP_PAO/",U9,"/","ImageServer/file?id=.\",S9,"\",R9,"_",Q9,"_",P9,"\",C9,"&rasterId=") -> https://sig.aminerals.cl/imgdyn/rest/services/CL_MLP_PAO/CL_MLP_PAO_IF_Ortho_ALL/ImageServer/file?id=.\El_Mauro_Puerto_Punta_Chungo_Drone\25_03_17\CL_MLP_PAO_IF_Ortho_25_03_17_NSTC_Km_120_a_121.tif&rasterId= | L9: CL | M9: MLP | N9: IF | O9: Ortho | P9: =TEXT(H9,"dd") -> 17 | Q9: =TEXT(H9,"MM") -> 03 | R9: =TEXT(H9,"YY") -> 25 | S9: El_Mauro_Puerto_Punta_Chungo_Drone | T9: 1 | U9: CL_MLP_PAO_IF_Ortho_ALL | V9: =RIGHT(D9,LEN(D9)-29) -> NSTC_Km_120_a_121 | W9: =E9 -> NSTC_Km_120_a_121 | X9: =V9=W9 -> TRUE | Y9: =VLOOKUP(D9,'Orden de Imagen'!$A$1:D149,4,FALSE()) -> 006 | Z9: =CONCATENATE(Y9,"_",R9,"_",Q9,"_",P9,"_",E9) -> 006_25_03_17_NSTC_Km_120_a_121
A10: 9 | B10: 20250319_Orejas16_Ruta-D-865.tif | C10: CL_MLP_PAO_IF_Ortho_25_03_19_Orejas16_Ruta-D-865.tiff | D10: =CONCATENATE(L10,"_",M10,"_",G10,"_",N10,"_",O10,"_",R10,"_",Q10,"_",P10,"_",E10) -> CL_MLP_PAO_IF_Ortho_25_03_19_Orejas16_Ruta-D-865 | E10: Orejas16_Ruta-D-865 | F10: DJI MATRICE 350 RTK | G10: PAO | H10: 45735.167 | I10: 45888 | J10: Activo | K10: =CONCATENATE("https://sig.aminerals.cl/imgdyn/rest/services/CL_MLP_PAO/",U10,"/","ImageServer/file?id=.\",S10,"\",R10,"_",Q10,"_",P10,"\",C10,"&rasterId=") -> https://sig.aminerals.cl/imgdyn/rest/services/CL_MLP_PAO/CL_MLP_PAO_IF_Ortho_ALL/ImageServer/file?id=.\El_Mauro_Puerto_Punta_Chungo_Drone\25_03_19\CL_MLP_PAO_IF_Ortho_25_03_19_Orejas16_Ruta-D-865.tiff&rasterId= | L10: CL | M10: MLP | N10: IF | O10: Ortho | P10: =TEXT(H10,"dd") -> 19 | Q10: =TEXT(H10,"MM") -> 03 | R10: =TEXT(H10,"YY") -> 25 | S10: El_Mauro_Puerto_Punta_Chungo_Drone | T10: 1 | U10: CL_MLP_PAO_IF_Ortho_ALL | V10: =RIGHT(D10,LEN(D10)-29) -> Orejas16_Ruta-D-865 | W10: =E10 -> Orejas16_Ruta-D-865 | X10: =V10=W10 -> TRUE | Y10: =VLOOKUP(D10,'Orden de Imagen'!$A$1:D150,4,FALSE()) -> 007 | Z10: =CONCATENATE(Y10,"_",R10,"_",Q10,"_",P10,"_",E10) -> 007_25_03_19_Orejas16_Ruta-D-865
A11: 10 | B11: 20250319_Orejas17_Ruta-D-865.tif | C11: CL_MLP_PAO_IF_Ortho_25_03_19_Orejas17_Ruta-D-865.tiff | D11: =CONCATENATE(L11,"_",M11,"_",G11,"_",N11,"_",O11,"_",R11,"_",Q11,"_",P11,"_",E11) -> CL_MLP_PAO_IF_Ortho_25_03_19_Orejas17_Ruta-D-865 | E11: Orejas17_Ruta-D-865 | F11: DJI MATRICE 350 RTK | G11: PAO | H11: 45735.167 | I11: 45888 | J11: Activo | K11: =CONCATENATE("https://sig.aminerals.cl/imgdyn/rest/services/CL_MLP_PAO/",U11,"/","ImageServer/file?id=.\",S11,"\",R11,"_",Q11,"_",P11,"\",C11,"&rasterId=") -> https://sig.aminerals.cl/imgdyn/rest/services/CL_MLP_PAO/CL_MLP_PAO_IF_Ortho_ALL/ImageServer/file?id=.\El_Mauro_Puerto_Punta_Chungo_Drone\25_03_19\CL_MLP_PAO_IF_Ortho_25_03_19_Orejas17_Ruta-D-865.tiff&rasterId= | L11: CL | M11: MLP | N11: IF | O11: Ortho | P11: =TEXT(H11,"dd") -> 19 | Q11: =TEXT(H11,"MM") -> 03 | R11: =TEXT(H11,"YY") -> 25 | S11: El_Mauro_Puerto_Punta_Chungo_Drone | T11: 1 | U11: CL_MLP_PAO_IF_Ortho_ALL | V11: =RIGHT(D11,LEN(D11)-29) -> Orejas17_Ruta-D-865 | W11: =E11 -> Orejas17_Ruta-D-865 | X11: =V11=W11 -> TRUE | Y11: =VLOOKUP(D11,'Orden de Imagen'!$A$1:D151,4,FALSE()) -> 008 | Z11: =CONCATENATE(Y11,"_",R11,"_",Q11,"_",P11,"_",E11) -> 008_25_03_19_Orejas17_Ruta-D-865
A12: 11 | B12: 20250319_Orejas18.tif | C12: CL_MLP_PAO_IF_Ortho_25_03_19_Orejas18.tiff | D12: =CONCATENATE(L12,"_",M12,"_",G12,"_",N12,"_",O12,"_",R12,"_",Q12,"_",P12,"_",E12) -> CL_MLP_PAO_IF_Ortho_25_03_19_Orejas18 | E12: Orejas18 | F12: DJI MATRICE 350 RTK | G12: PAO | H12: 45735.167 | I12: 45870 | J12: Activo | K12: =CONCATENATE("https://sig.aminerals.cl/imgdyn/rest/services/CL_MLP_PAO/",U12,"/","ImageServer/file?id=.\",S12,"\",R12,"_",Q12,"_",P12,"\",C12,"&rasterId=") -> https://sig.aminerals.cl/imgdyn/rest/services/CL_MLP_PAO/CL_MLP_PAO_IF_Ortho_ALL/ImageServer/file?id=.\El_Mauro_Puerto_Punta_Chungo_Drone\25_03_19\CL_MLP_PAO_IF_Ortho_25_03_19_Orejas18.tiff&rasterId= | L12: CL | M12: MLP | N12: IF | O12: Ortho | P12: =TEXT(H12,"dd") -> 19 | Q12: =TEXT(H12,"MM") -> 03 | R12: =TEXT(H12,"YY") -> 25 | S12: El_Mauro_Puerto_Punta_Chungo_Drone | T12: 1 | U12: CL_MLP_PAO_IF_Ortho_ALL | V12: =RIGHT(D12,LEN(D12)-29) -> Orejas18 | W12: =E12 -> Orejas18 | X12: =V12=W12 -> TRUE | Y12: =VLOOKUP(D12,'Orden de Imagen'!$A$1:D152,4,FALSE()) -> 009 | Z12: =CONCATENATE(Y12,"_",R12,"_",Q12,"_",P12,"_",E12) -> 009_25_03_19_Orejas18
A13: 12 | B13: 20250331_EB2.tif | C13: CL_MLP_PAO_IF_Ortho_25_03_31_EB2.tiff | D13: =CONCATENATE(L13,"_",M13,"_",G13,"_",N13,"_",O13,"_",R13,"_",Q13,"_",P13,"_",E13) -> CL_MLP_PAO_IF_Ortho_25_03_31_EB2 | E13: EB2 | F13: DJI MATRICE 350 RTK | G13: PAO | H13: 45747.167 | I13: 45870 | J13: Activo | K13: =CONCATENATE("https://sig.aminerals.cl/imgdyn/rest/services/CL_MLP_PAO/",U13,"/","ImageServer/file?id=.\",S13,"\",R13,"_",Q13,"_",P13,"\",C13,"&rasterId=") -> https://sig.aminerals.cl/imgdyn/rest/services/CL_MLP_PAO/CL_MLP_PAO_IF_Ortho_ALL/ImageServer/file?id=.\El_Mauro_Puerto_Punta_Chungo_Drone\25_03_31\CL_MLP_PAO_IF_Ortho_25_03_31_EB2.tiff&rasterId= | L13: CL | M13: MLP | N13: IF | O13: Ortho | P13: =TEXT(H13,"dd") -> 31 | Q13: =TEXT(H13,"MM") -> 03 | R13: =TEXT(H13,"YY") -> 25 | S13: El_Mauro_Puerto_Punta_Chungo_Drone | T13: 1 | U13: CL_MLP_PAO_IF_Ortho_ALL | V13: =RIGHT(D13,LEN(D13)-29) -> EB2 | W13: =E13 -> EB2 | X13: =V13=W13 -> TRUE | Y13: =VLOOKUP(D13,'Orden de Imagen'!$A$1:D153,4,FALSE()) -> 010 | Z13: =CONCATENATE(Y13,"_",R13,"_",Q13,"_",P13,"_",E13) -> 010_25_03_31_EB2
A14: 13 | B14: 20250331_EV2.tif | C14: CL_MLP_PAO_IF_Ortho_25_03_31_EV2.tiff | D14: =CONCATENATE(L14,"_",M14,"_",G14,"_",N14,"_",O14,"_",R14,"_",Q14,"_",P14,"_",E14) -> CL_MLP_PAO_IF_Ortho_25_03_31_EV2 | E14: EV2 | F14: DJI MATRICE 350 RTK | G14: PAO | H14: 45747.167 | I14: 45870 | J14: Activo | K14: =CONCATENATE("https://sig.aminerals.cl/imgdyn/rest/services/CL_MLP_PAO/",U14,"/","ImageServer/file?id=.\",S14,"\",R14,"_",Q14,"_",P14,"\",C14,"&rasterId=") -> https://sig.aminerals.cl/imgdyn/rest/services/CL_MLP_PAO/CL_MLP_PAO_IF_Ortho_ALL/ImageServer/file?id=.\El_Mauro_Puerto_Punta_Chungo_Drone\25_03_31\CL_MLP_PAO_IF_Ortho_25_03_31_EV2.tiff&rasterId= | L14: CL | M14: MLP | N14: IF | O14: Ortho | P14: =TEXT(H14,"dd") -> 31 | Q14: =TEXT(H14,"MM") -> 03 | R14: =TEXT(H14,"YY") -> 25 | S14: El_Mauro_Puerto_Punta_Chungo_Drone | T14: 1 | U14: CL_MLP_PAO_IF_Ortho_ALL | V14: =RIGHT(D14,LEN(D14)-29) -> EV2 | W14: =E14 -> EV2 | X14: =V14=W14 -> TRUE | Y14: =VLOOKUP(D14,'Orden de Imagen'!$A$1:D154,4,FALSE()) -> 011 | Z14: =CONCATENATE(Y14,"_",R14,"_",Q14,"_",P14,"_",E14) -> 011_25_03_31_EV2
A15: 14 | B15: 20250402_DME-13.tiff | C15: CL_MLP_PAO_IF_Ortho_25_04_02_DME-13.tiff | D15: =CONCATENATE(L15,"_",M15,"_",G15,"_",N15,"_",O15,"_",R15,"_",Q15,"_",P15,"_",E15) -> CL_MLP_PAO_IF_Ortho_25_04_02_DME-13 | E15: DME-13 | F15: DJI MATRICE 350 RTK | G15: PAO | H15: 45749.167 | I15: 45870 | J15: Activo | K15: =CONCATENATE("https://sig.aminerals.cl/imgdyn/rest/services/CL_MLP_PAO/",U15,"/","ImageServer/file?id=.\",S15,"\",R15,"_",Q15,"_",P15,"\",C15,"&rasterId=") -> https://sig.aminerals.cl/imgdyn/rest/services/CL_MLP_PAO/CL_MLP_PAO_IF_Ortho_ALL/ImageServer/file?id=.\Chacay_El_Mauro_Drone\25_04_02\CL_MLP_PAO_IF_Ortho_25_04_02_DME-13.tiff&rasterId= | L15: CL | M15: MLP | N15: IF | O15: Ortho | P15: =TEXT(H15,"dd") -> 02 | Q15: =TEXT(H15,"MM") -> 04 | R15: =TEXT(H15,"YY") -> 25 | S15: Chacay_El_Mauro_Drone | T15: 1 | U15: CL_MLP_PAO_IF_Ortho_ALL | V15: =RIGHT(D15,LEN(D15)-29) -> DME-13 | W15: =E15 -> DME-13 | X15: =V15=W15 -> TRUE | Y15: =VLOOKUP(D15,'Orden de Imagen'!$A$1:D155,4,FALSE()) -> 012 | Z15: =CONCATENATE(Y15,"_",R15,"_",Q15,"_",P15,"_",E15) -> 012_25_04_02_DME-13
A16: 15 | B16: 20250402_Patio-Acopio-17_reprocesado-Orthomosaic.tiff | C16: CL_MLP_PAO_IF_Ortho_25_04_02_Patio-Acopio-17.tiff | D16: =CONCATENATE(L16,"_",M16,"_",G16,"_",N16,"_",O16,"_",R16,"_",Q16,"_",P16,"_",E16) -> CL_MLP_PAO_IF_Ortho_25_04_02_Patio-Acopio-17 | E16: Patio-Acopio-17 | F16: DJI MATRICE 350 RTK | G16: PAO | H16: 45749.167 | I16: 45872 | J16: Activo | K16: =CONCATENATE("https://sig.aminerals.cl/imgdyn/rest/services/CL_MLP_PAO/",U16,"/","ImageServer/file?id=.\",S16,"\",R16,"_",Q16,"_",P16,"\",C16,"&rasterId=") -> https://sig.aminerals.cl/imgdyn/rest/services/CL_MLP_PAO/CL_MLP_PAO_IF_Ortho_ALL/ImageServer/file?id=.\Chacay_El_Mauro_Drone\25_04_02\CL_MLP_PAO_IF_Ortho_25_04_02_Patio-Acopio-17.tiff&rasterId= | L16: CL | M16: MLP | N16: IF | O16: Ortho | P16: =TEXT(H16,"dd") -> 02 | Q16: =TEXT(H16,"MM") -> 04 | R16: =TEXT(H16,"YY") -> 25 | S16: Chacay_El_Mauro_Drone | T16: 1 | U16: CL_MLP_PAO_IF_Ortho_ALL | V16: =RIGHT(D16,LEN(D16)-29) -> Patio-Acopio-17 | W16: =E16 -> Patio-Acopio-17 | X16: =V16=W16 -> TRUE | Y16: =VLOOKUP(D16,'Orden de Imagen'!$A$1:D156,4,FALSE()) -> 013 | Z16: =CONCATENATE(Y16,"_",R16,"_",Q16,"_",P16,"_",E16) -> 013_25_04_02_Patio-Acopio-17
A17: 16 | B17: 20250402_Ruta-SE-a-DME-13-Orthomosaic.tiff | C17: CL_MLP_PAO_IF_Ortho_25_04_02_Ruta-SE-a-DME-13.tiff | D17: =CONCATENATE(L17,"_",M17,"_",G17,"_",N17,"_",O17,"_",R17,"_",Q17,"_",P17,"_",E17) -> CL_MLP_PAO_IF_Ortho_25_04_02_Ruta-SE-a-DME-13 | E17: Ruta-SE-a-DME-13 | F17: DJI MATRICE 350 RTK | G17: PAO | H17: 45749.167 | I17: 45873 | J17: Activo | K17: =CONCATENATE("https://sig.aminerals.cl/imgdyn/rest/services/CL_MLP_PAO/",U17,"/","ImageServer/file?id=.\",S17,"\",R17,"_",Q17,"_",P17,"\",C17,"&rasterId=") -> https://sig.aminerals.cl/imgdyn/rest/services/CL_MLP_PAO/CL_MLP_PAO_IF_Ortho_ALL/ImageServer/file?id=.\Chacay_El_Mauro_Drone\25_04_02\CL_MLP_PAO_IF_Ortho_25_04_02_Ruta-SE-a-DME-13.tiff&rasterId= | L17: CL | M17: MLP | N17: IF | O17: Ortho | P17: =TEXT(H17,"dd") -> 02 | Q17: =TEXT(H17,"MM") -> 04 | R17: =TEXT(H17,"YY") -> 25 | S17: Chacay_El_Mauro_Drone | T17: 1 | U17: CL_MLP_PAO_IF_Ortho_ALL | V17: =RIGHT(D17,LEN(D17)-29) -> Ruta-SE-a-DME-13 | W17: =E17 -> Ruta-SE-a-DME-13 | X17: =V17=W17 -> TRUE | Y17: =VLOOKUP(D17,'Orden de Imagen'!$A$1:D157,4,FALSE()) -> 014 | Z17: =CONCATENATE(Y17,"_",R17,"_",Q17,"_",P17,"_",E17) -> 014_25_04_02_Ruta-SE-a-DME-13
A18: 17 | B18: 20250403_Area-patio-19b-y-armado-Orthomosaic.tiff | C18: CL_MLP_PAO_IF_Ortho_25_04_03_Area-patio-19b-y-armado.tiff | D18: =CONCATENATE(L18,"_",M18,"_",G18,"_",N18,"_",O18,"_",R18,"_",Q18,"_",P18,"_",E18) -> CL_MLP_PAO_IF_Ortho_25_04_03_Area-patio-19b-y-armado | E18: Area-patio-19b-y-armado | F18: DJI MATRICE 350 RTK | G18: PAO | H18: 45750.167 | I18: 45868 | J18: Activo | K18: =CONCATENATE("https://sig.aminerals.cl/imgdyn/rest/services/CL_MLP_PAO/",U18,"/","ImageServer/file?id=.\",S18,"\",R18,"_",Q18,"_",P18,"\",C18,"&rasterId=") -> https://sig.aminerals.cl/imgdyn/rest/services/CL_MLP_PAO/CL_MLP_PAO_IF_Ortho_ALL/ImageServer/file?id=.\El_Mauro_Drone\25_04_03\CL_MLP_PAO_IF_Ortho_25_04_03_Area-patio-19b-y-armado.tiff&rasterId= | L18: CL | M18: MLP | N18: IF | O18: Ortho | P18: =TEXT(H18,"dd") -> 03 | Q18: =TEXT(H18,"MM") -> 04 | R18: =TEXT(H18,"YY") -> 25 | S18: El_Mauro_Drone | T18: 1 | U18: CL_MLP_PAO_IF_Ortho_ALL | V18: =RIGHT(D18,LEN(D18)-29) -> Area-patio-19b-y-armado | W18: =E18 -> Area-patio-19b-y-armado | X18: =V18=W18 -> TRUE | Y18: =VLOOKUP(D18,'Orden de Imagen'!$A$1:D158,4,FALSE()) -> 015 | Z18: =CONCATENATE(Y18,"_",R18,"_",Q18,"_",P18,"_",E18) -> 015_25_04_03_Area-patio-19b-y-armado
A19: 18 | B19: 20250403_Subestación-El-Mauro-Orthomosaic.tiff | C19: CL_MLP_PAO_IF_Ortho_25_04_03_Subestacion-El-Mauro.tiff | D19: =CONCATENATE(L19,"_",M19,"_",G19,"_",N19,"_",O19,"_",R19,"_",Q19,"_",P19,"_",E19) -> CL_MLP_PAO_IF_Ortho_25_04_03_Subestacion-El-Mauro | E19: Subestacion-El-Mauro | F19: DJI MATRICE 350 RTK | G19: PAO | H19: 45750.167 | I19: 45869 | J19: Activo | K19: =CONCATENATE("https://sig.aminerals.cl/imgdyn/rest/services/CL_MLP_PAO/",U19,"/","ImageServer/file?id=.\",S19,"\",R19,"_",Q19,"_",P19,"\",C19,"&rasterId=") -> https://sig.aminerals.cl/imgdyn/rest/services/CL_MLP_PAO/CL_MLP_PAO_IF_Ortho_ALL/ImageServer/file?id=.\El_Mauro_Drone\25_04_03\CL_MLP_PAO_IF_Ortho_25_04_03_Subestacion-El-Mauro.tiff&rasterId= | L19: CL | M19: MLP | N19: IF | O19: Ortho | P19: =TEXT(H19,"dd") -> 03 | Q19: =TEXT(H19,"MM") -> 04 | R19: =TEXT(H19,"YY") -> 25 | S19: El_Mauro_Drone | T19: 1 | U19: CL_MLP_PAO_IF_Ortho_ALL | V19: =RIGHT(D19,LEN(D19)-29) -> Subestacion-El-Mauro | W19: =E19 -> Subestacion-El-Mauro | X19: =V19=W19 -> TRUE | Y19: =VLOOKUP(D19,'Orden de Imagen'!$A$1:D159,4,FALSE()) -> 016 | Z19: =CONCATENATE(Y19,"_",R19,"_",Q19,"_",P19,"_",E19) -> 016_25_04_03_Subestacion-El-Mauro
A20: 19 | C20: =CONCATENATE(L20,"_",M20,"_",G20,"_",N20,"_",O20,"_",R20,"_",Q20,"_",P20,"_",E20,".tif") -> CL_MLP_PAO_IF_Ortho_25_04_09_Cachimba_de_Bajo_Camisas_ED2.tif | D20: =CONCATENATE(L20,"_",M20,"_",G20,"_",N20,"_",O20,"_",R20,"_",Q20,"_",P20,"_",E20) -> CL_MLP_PAO_IF_Ortho_25_04_09_Cachimba_de_Bajo_Camisas_ED2 | E20: Cachimba_de_Bajo_Camisas_ED2 | F20: DJI MATRICE 350 RTK | G20: PAO | H20: 45756.167 | I20: 45933 | J20: Activo | K20: =CONCATENATE("https://sig.aminerals.cl/imgdyn/rest/services/CL_MLP_PAO/",U20,"/","ImageServer/file?id=.\",S20,"\",R20,"_",Q20,"_",P20,"\",C20,"&rasterId=") -> https://sig.aminerals.cl/imgdyn/rest/services/CL_MLP_PAO/CL_MLP_PAO_IF_Ortho_ALL/ImageServer/file?id=.\Chacay_El_Mauro_Drone\25_04_09\CL_MLP_PAO_IF_Ortho_25_04_09_Cachimba_de_Bajo_Camisas_ED2.tif&rasterId= | L20: CL | M20: MLP | N20: IF | O20: Ortho | P20: =TEXT(H20,"dd") -> 09 | Q20: =TEXT(H20,"MM") -> 04 | R20: =TEXT(H20,"YY") -> 25 | S20: Chacay_El_Mauro_Drone | T20: 1 | U20: CL_MLP_PAO_IF_Ortho_ALL | V20: =RIGHT(D20,LEN(D20)-29) -> Cachimba_de_Bajo_Camisas_ED2 | W20: =E20 -> Cachimba_de_Bajo_Camisas_ED2 | X20: =V20=W20 -> TRUE | Y20: =VLOOKUP(D20,'Orden de Imagen'!$A$1:D160,4,FALSE()) -> 017 | Z20: =CONCATENATE(Y20,"_",R20,"_",Q20,"_",P20,"_",E20) -> 017_25_04_09_Cachimba_de_Bajo_Camisas_ED2
A21: 20 | B21: 20250409_Ruta-D-847_01.tif | C21: CL_MLP_PAO_IF_Ortho_25_04_09_Ruta-D-847_01.tiff | D21: =CONCATENATE(L21,"_",M21,"_",G21,"_",N21,"_",O21,"_",R21,"_",Q21,"_",P21,"_",E21) -> CL_MLP_PAO_IF_Ortho_25_04_09_Ruta-D-847_01 | E21: Ruta-D-847_01 | F21: DJI MATRICE 350 RTK | G21: PAO | H21: 45756.167 | I21: 45874 | J21: Activo | K21: =CONCATENATE("https://sig.aminerals.cl/imgdyn/rest/services/CL_MLP_PAO/",U21,"/","ImageServer/file?id=.\",S21,"\",R21,"_",Q21,"_",P21,"\",C21,"&rasterId=") -> https://sig.aminerals.cl/imgdyn/rest/services/CL_MLP_PAO/CL_MLP_PAO_IF_Ortho_ALL/ImageServer/file?id=.\Chacay_El_Mauro_Drone\25_04_09\CL_MLP_PAO_IF_Ortho_25_04_09_Ruta-D-847_01.tiff&rasterId= | L21: CL | M21: MLP | N21: IF | O21: Ortho | P21: =TEXT(H21,"dd") -> 09 | Q21: =TEXT(H21,"MM") -> 04 | R21: =TEXT(H21,"YY") -> 25 | S21: Chacay_El_Mauro_Drone | T21: 1 | U21: CL_MLP_PAO_IF_Ortho_ALL | V21: =RIGHT(D21,LEN(D21)-29) -> Ruta-D-847_01 | W21: =E21 -> Ruta-D-847_01 | X21: =V21=W21 -> TRUE | Y21: =VLOOKUP(D21,'Orden de Imagen'!$A$1:D161,4,FALSE()) -> #N/A | Z21: =CONCATENATE(Y21,"_",R21,"_",Q21,"_",P21,"_",E21) -> #N/A
A22: 21 | B22: 20250409_Ruta-D-847_02.tif | C22: CL_MLP_PAO_IF_Ortho_25_04_09_Ruta-D-847_02.tiff | D22: =CONCATENATE(L22,"_",M22,"_",G22,"_",N22,"_",O22,"_",R22,"_",Q22,"_",P22,"_",E22) -> CL_MLP_PAO_IF_Ortho_25_04_09_Ruta-D-847_02 | E22: Ruta-D-847_02 | F22: DJI MATRICE 350 RTK | G22: PAO | H22: 45756.167 | I22: 45875 | J22: Activo | K22: =CONCATENATE("https://sig.aminerals.cl/imgdyn/rest/services/CL_MLP_PAO/",U22,"/","ImageServer/file?id=.\",S22,"\",R22,"_",Q22,"_",P22,"\",C22,"&rasterId=") -> https://sig.aminerals.cl/imgdyn/rest/services/CL_MLP_PAO/CL_MLP_PAO_IF_Ortho_ALL/ImageServer/file?id=.\Chacay_El_Mauro_Drone\25_04_09\CL_MLP_PAO_IF_Ortho_25_04_09_Ruta-D-847_02.tiff&rasterId= | L22: CL | M22: MLP | N22: IF | O22: Ortho | P22: =TEXT(H22,"dd") -> 09 | Q22: =TEXT(H22,"MM") -> 04 | R22: =TEXT(H22,"YY") -> 25 | S22: Chacay_El_Mauro_Drone | T22: 1 | U22: CL_MLP_PAO_IF_Ortho_ALL | V22: =RIGHT(D22,LEN(D22)-29) -> Ruta-D-847_02 | W22: =E22 -> Ruta-D-847_02 | X22: =V22=W22 -> TRUE | Y22: =VLOOKUP(D22,'Orden de Imagen'!$A$1:D162,4,FALSE()) -> #N/A | Z22: =CONCATENATE(Y22,"_",R22,"_",Q22,"_",P22,"_",E22) -> #N/A
A23: 22 | B23: 20250409_Ruta-D-847_03.tif | C23: CL_MLP_PAO_IF_Ortho_25_04_09_Ruta-D-847_03.tiff | D23: =CONCATENATE(L23,"_",M23,"_",G23,"_",N23,"_",O23,"_",R23,"_",Q23,"_",P23,"_",E23) -> CL_MLP_PAO_IF_Ortho_25_04_09_Ruta-D-847_03 | E23: Ruta-D-847_03 | F23: DJI MATRICE 350 RTK | G23: PAO | H23: 45756.167 | I23: 45876 | J23: Activo | K23: =CONCATENATE("https://sig.aminerals.cl/imgdyn/rest/services/CL_MLP_PAO/",U23,"/","ImageServer/file?id=.\",S23,"\",R23,"_",Q23,"_",P23,"\",C23,"&rasterId=") -> https://sig.aminerals.cl/imgdyn/rest/services/CL_MLP_PAO/CL_MLP_PAO_IF_Ortho_ALL/ImageServer/file?id=.\Chacay_El_Mauro_Drone\25_04_09\CL_MLP_PAO_IF_Ortho_25_04_09_Ruta-D-847_03.tiff&rasterId= | L23: CL | M23: MLP | N23: IF | O23: Ortho | P23: =TEXT(H23,"dd") -> 09 | Q23: =TEXT(H23,"MM") -> 04 | R23: =TEXT(H23,"YY") -> 25 | S23: Chacay_El_Mauro_Drone | T23: 1 | U23: CL_MLP_PAO_IF_Ortho_ALL | V23: =RIGHT(D23,LEN(D23)-29) -> Ruta-D-847_03 | W23: =E23 -> Ruta-D-847_03 | X23: =V23=W23 -> TRUE | Y23: =VLOOKUP(D23,'Orden de Imagen'!$A$1:D163,4,FALSE()) -> #N/A | Z23: =CONCATENATE(Y23,"_",R23,"_",Q23,"_",P23,"_",E23) -> #N/A
A24: 23 | B24: 20250410_Ruta-D-865_01.tif | C24: CL_MLP_PAO_IF_Ortho_25_04_10_Ruta-D-865_01.tiff | D24: =CONCATENATE(L24,"_",M24,"_",G24,"_",N24,"_",O24,"_",R24,"_",Q24,"_",P24,"_",E24) -> CL_MLP_PAO_IF_Ortho_25_04_10_Ruta-D-865_01 | E24: Ruta-D-865_01 | F24: DJI MATRICE 350 RTK | G24: PAO | H24: 45757.167 | I24: 45870 | J24: Activo | K24: =CONCATENATE("https://sig.aminerals.cl/imgdyn/rest/services/CL_MLP_PAO/",U24,"/","ImageServer/file?id=.\",S24,"\",R24,"_",Q24,"_",P24,"\",C24,"&rasterId=") -> https://sig.aminerals.cl/imgdyn/rest/services/CL_MLP_PAO/CL_MLP_PAO_IF_Ortho_ALL/ImageServer/file?id=.\El_Mauro_Puerto_Punta_Chungo_Drone\25_04_10\CL_MLP_PAO_IF_Ortho_25_04_10_Ruta-D-865_01.tiff&rasterId= | L24: CL | M24: MLP | N24: IF | O24: Ortho | P24: =TEXT(H24,"dd") -> 10 | Q24: =TEXT(H24,"MM") -> 04 | R24: =TEXT(H24,"YY") -> 25 | S24: El_Mauro_Puerto_Punta_Chungo_Drone | T24: 1 | U24: CL_MLP_PAO_IF_Ortho_ALL | V24: =RIGHT(D24,LEN(D24)-29) -> Ruta-D-865_01 | W24: =E24 -> Ruta-D-865_01 | X24: =V24=W24 -> TRUE | Y24: =VLOOKUP(D24,'Orden de Imagen'!$A$1:D164,4,FALSE()) -> #N/A | Z24: =CONCATENATE(Y24,"_",R24,"_",Q24,"_",P24,"_",E24) -> #N/A
A25: 24 | B25: 20250410_Ruta-D-865_02.tif | C25: CL_MLP_PAO_IF_Ortho_25_04_10_Ruta-D-865_02.tiff | D25: =CONCATENATE(L25,"_",M25,"_",G25,"_",N25,"_",O25,"_",R25,"_",Q25,"_",P25,"_",E25) -> CL_MLP_PAO_IF_Ortho_25_04_10_Ruta-D-865_02 | E25: Ruta-D-865_02 | F25: DJI MATRICE 350 RTK | G25: PAO | H25: 45757.167 | I25: 45870 | J25: Activo | K25: =CONCATENATE("https://sig.aminerals.cl/imgdyn/rest/services/CL_MLP_PAO/",U25,"/","ImageServer/file?id=.\",S25,"\",R25,"_",Q25,"_",P25,"\",C25,"&rasterId=") -> https://sig.aminerals.cl/imgdyn/rest/services/CL_MLP_PAO/CL_MLP_PAO_IF_Ortho_ALL/ImageServer/file?id=.\El_Mauro_Puerto_Punta_Chungo_Drone\25_04_10\CL_MLP_PAO_IF_Ortho_25_04_10_Ruta-D-865_02.tiff&rasterId= | L25: CL | M25: MLP | N25: IF | O25: Ortho | P25: =TEXT(H25,"dd") -> 10 | Q25: =TEXT(H25,"MM") -> 04 | R25: =TEXT(H25,"YY") -> 25 | S25: El_Mauro_Puerto_Punta_Chungo_Drone | T25: 1 | U25: CL_MLP_PAO_IF_Ortho_ALL | V25: =RIGHT(D25,LEN(D25)-29) -> Ruta-D-865_02 | W25: =E25 -> Ruta-D-865_02 | X25: =V25=W25 -> TRUE | Y25: =VLOOKUP(D25,'Orden de Imagen'!$A$1:D165,4,FALSE()) -> #N/A | Z25: =CONCATENATE(Y25,"_",R25,"_",Q25,"_",P25,"_",E25) -> #N/A
A26: 25 | B26: 20250410_Ruta-D-865_03.tif | C26: CL_MLP_PAO_IF_Ortho_25_04_10_Ruta-D-865_03.tiff | D26: =CONCATENATE(L26,"_",M26,"_",G26,"_",N26,"_",O26,"_",R26,"_",Q26,"_",P26,"_",E26) -> CL_MLP_PAO_IF_Ortho_25_04_10_Ruta-D-865_03 | E26: Ruta-D-865_03 | F26: DJI MATRICE 350 RTK | G26: PAO | H26: 45757.167 | I26: 45870 | J26: Activo | K26: =CONCATENATE("https://sig.aminerals.cl/imgdyn/rest/services/CL_MLP_PAO/",U26,"/","ImageServer/file?id=.\",S26,"\",R26,"_",Q26,"_",P26,"\",C26,"&rasterId=") -> https://sig.aminerals.cl/imgdyn/rest/services/CL_MLP_PAO/CL_MLP_PAO_IF_Ortho_ALL/ImageServer/file?id=.\El_Mauro_Puerto_Punta_Chungo_Drone\25_04_10\CL_MLP_PAO_IF_Ortho_25_04_10_Ruta-D-865_03.tiff&rasterId= | L26: CL | M26: MLP | N26: IF | O26: Ortho | P26: =TEXT(H26,"dd") -> 10 | Q26: =TEXT(H26,"MM") -> 04 | R26: =TEXT(H26,"YY") -> 25 | S26: El_Mauro_Puerto_Punta_Chungo_Drone | T26: 1 | U26: CL_MLP_PAO_IF_Ortho_ALL | V26: =RIGHT(D26,LEN(D26)-29) -> Ruta-D-865_03 | W26: =E26 -> Ruta-D-865_03 | X26: =V26=W26 -> TRUE | Y26: =VLOOKUP(D26,'Orden de Imagen'!$A$1:D166,4,FALSE()) -> #N/A | Z26: =CONCATENATE(Y26,"_",R26,"_",Q26,"_",P26,"_",E26) -> #N/A
A27: 26 | B27: 20250410_Ruta-D-865_04.tif | C27: CL_MLP_PAO_IF_Ortho_25_04_10_Ruta-D-865_04.tiff | D27: =CONCATENATE(L27,"_",M27,"_",G27,"_",N27,"_",O27,"_",R27,"_",Q27,"_",P27,"_",E27) -> CL_MLP_PAO_IF_Ortho_25_04_10_Ruta-D-865_04 | E27: Ruta-D-865_04 | F27: DJI MATRICE 350 RTK | G27: PAO | H27: 45757.167 | I27: 45870 | J27: Activo | K27: =CONCATENATE("https://sig.aminerals.cl/imgdyn/rest/services/CL_MLP_PAO/",U27,"/","ImageServer/file?id=.\",S27,"\",R27,"_",Q27,"_",P27,"\",C27,"&rasterId=") -> https://sig.aminerals.cl/imgdyn/rest/services/CL_MLP_PAO/CL_MLP_PAO_IF_Ortho_ALL/ImageServer/file?id=.\El_Mauro_Puerto_Punta_Chungo_Drone\25_04_10\CL_MLP_PAO_IF_Ortho_25_04_10_Ruta-D-865_04.tiff&rasterId= | L27: CL | M27: MLP | N27: IF | O27: Ortho | P27: =TEXT(H27,"dd") -> 10 | Q27: =TEXT(H27,"MM") -> 04 | R27: =TEXT(H27,"YY") -> 25 | S27: El_Mauro_Puerto_Punta_Chungo_Drone | T27: 1 | U27: CL_MLP_PAO_IF_Ortho_ALL | V27: =RIGHT(D27,LEN(D27)-29) -> Ruta-D-865_04 | W27: =E27 -> Ruta-D-865_04 | X27: =V27=W27 -> TRUE | Y27: =VLOOKUP(D27,'Orden de Imagen'!$A$1:D167,4,FALSE()) -> #N/A | Z27: =CONCATENATE(Y27,"_",R27,"_",Q27,"_",P27,"_",E27) -> #N/A
A28: 27 | B28: 20250410_Ruta-D-865_05.tif | C28: CL_MLP_PAO_IF_Ortho_25_04_10_Ruta-D-865_05.tiff | D28: =CONCATENATE(L28,"_",M28,"_",G28,"_",N28,"_",O28,"_",R28,"_",Q28,"_",P28,"_",E28) -> CL_MLP_PAO_IF_Ortho_25_04_10_Ruta-D-865_05 | E28: Ruta-D-865_05 | F28: DJI MATRICE 350 RTK | G28: PAO | H28: 45757.167 | I28: 45870 | J28: Activo | K28: =CONCATENATE("https://sig.aminerals.cl/imgdyn/rest/services/CL_MLP_PAO/",U28,"/","ImageServer/file?id=.\",S28,"\",R28,"_",Q28,"_",P28,"\",C28,"&rasterId=") -> https://sig.aminerals.cl/imgdyn/rest/services/CL_MLP_PAO/CL_MLP_PAO_IF_Ortho_ALL/ImageServer/file?id=.\El_Mauro_Puerto_Punta_Chungo_Drone\25_04_10\CL_MLP_PAO_IF_Ortho_25_04_10_Ruta-D-865_05.tiff&rasterId= | L28: CL | M28: MLP | N28: IF | O28: Ortho | P28: =TEXT(H28,"dd") -> 10 | Q28: =TEXT(H28,"MM") -> 04 | R28: =TEXT(H28,"YY") -> 25 | S28: El_Mauro_Puerto_Punta_Chungo_Drone | T28: 1 | U28: CL_MLP_PAO_IF_Ortho_ALL | V28: =RIGHT(D28,LEN(D28)-29) -> Ruta-D-865_05 | W28: =E28 -> Ruta-D-865_05 | X28: =V28=W28 -> TRUE | Y28: =VLOOKUP(D28,'Orden de Imagen'!$A$1:D168,4,FALSE()) -> #N/A | Z28: =CONCATENATE(Y28,"_",R28,"_",Q28,"_",P28,"_",E28) -> #N/A
A29: 28 | C29: =CONCATENATE(L29,"_",M29,"_",G29,"_",N29,"_",O29,"_",R29,"_",Q29,"_",P29,"_",E29,".tiff") -> CL_MLP_PAO_IF_Ortho_25_04_10_Sector_Pupio_I_Area_1.tiff | D29: =CONCATENATE(L29,"_",M29,"_",G29,"_",N29,"_",O29,"_",R29,"_",Q29,"_",P29,"_",E29) -> CL_MLP_PAO_IF_Ortho_25_04_10_Sector_Pupio_I_Area_1 | E29: Sector_Pupio_I_Area_1 | F29: DJI MATRICE 350 RTK | G29: PAO | H29: 45757.167 | I29: 45933 | J29: Activo | K29: =CONCATENATE("https://sig.aminerals.cl/imgdyn/rest/services/CL_MLP_PAO/",U29,"/","ImageServer/file?id=.\",S29,"\",R29,"_",Q29,"_",P29,"\",C29,"&rasterId=") -> https://sig.aminerals.cl/imgdyn/rest/services/CL_MLP_PAO/CL_MLP_PAO_IF_Ortho_ALL/ImageServer/file?id=.\El_Mauro_Puerto_Punta_Chungo_Drone\25_04_10\CL_MLP_PAO_IF_Ortho_25_04_10_Sector_Pupio_I_Area_1.tiff&rasterId= | L29: CL | M29: MLP | N29: IF | O29: Ortho | P29: =TEXT(H29,"dd") -> 10 | Q29: =TEXT(H29,"MM") -> 04 | R29: =TEXT(H29,"YY") -> 25 | S29: El_Mauro_Puerto_Punta_Chungo_Drone | T29: 1 | U29: CL_MLP_PAO_IF_Ortho_ALL | V29: =RIGHT(D29,LEN(D29)-29) -> Sector_Pupio_I_Area_1 | W29: =E29 -> Sector_Pupio_I_Area_1 | X29: =V29=W29 -> TRUE | Y29: =VLOOKUP(D29,'Orden de Imagen'!$A$1:D169,4,FALSE()) -> 018 | Z29: =CONCATENATE(Y29,"_",R29,"_",Q29,"_",P29,"_",E29) -> 018_25_04_10_Sector_Pupio_I_Area_1
A30: 29 | C30: =CONCATENATE(L30,"_",M30,"_",G30,"_",N30,"_",O30,"_",R30,"_",Q30,"_",P30,"_",E30,".tiff") -> CL_MLP_PAO_IF_Ortho_25_05_07_Monte_Aranda_82p3_a_80p7.tiff | D30: =CONCATENATE(L30,"_",M30,"_",G30,"_",N30,"_",O30,"_",R30,"_",Q30,"_",P30,"_",E30) -> CL_MLP_PAO_IF_Ortho_25_05_07_Monte_Aranda_82p3_a_80p7 | E30: Monte_Aranda_82p3_a_80p7 | F30: DJI MATRICE 350 RTK | G30: PAO | H30: 45784.167 | I30: 45933 | J30: Activo | K30: =CONCATENATE("https://sig.aminerals.cl/imgdyn/rest/services/CL_MLP_PAO/",U30,"/","ImageServer/file?id=.\",S30,"\",R30,"_",Q30,"_",P30,"\",C30,"&rasterId=") -> https://sig.aminerals.cl/imgdyn/rest/services/CL_MLP_PAO/CL_MLP_PAO_IF_Ortho_ALL/ImageServer/file?id=.\El_Mauro_Puerto_Punta_Chungo_Drone\25_05_07\CL_MLP_PAO_IF_Ortho_25_05_07_Monte_Aranda_82p3_a_80p7.tiff&rasterId= | L30: CL | M30: MLP | N30: IF | O30: Ortho | P30: =TEXT(H30,"dd") -> 07 | Q30: =TEXT(H30,"MM") -> 05 | R30: =TEXT(H30,"YY") -> 25 | S30: El_Mauro_Puerto_Punta_Chungo_Drone | T30: 1 | U30: CL_MLP_PAO_IF_Ortho_ALL | V30: =RIGHT(D30,LEN(D30)-29) -> Monte_Aranda_82p3_a_80p7 | W30: Monte_Aranda_82p3_a_80p7 | X30: =V30=W30 -> TRUE | Y30: =VLOOKUP(D30,'Orden de Imagen'!$A$1:D170,4,FALSE()) -> 019 | Z30: =CONCATENATE(Y30,"_",R30,"_",Q30,"_",P30,"_",E30) -> 019_25_05_07_Monte_Aranda_82p3_a_80p7
A31: 30 | C31: =CONCATENATE(L31,"_",M31,"_",G31,"_",N31,"_",O31,"_",R31,"_",Q31,"_",P31,"_",E31,".tiff") -> CL_MLP_PAO_IF_Ortho_25_05_07_Monte-Aranda-84p2-a-82p3.tiff | D31: =CONCATENATE(L31,"_",M31,"_",G31,"_",N31,"_",O31,"_",R31,"_",Q31,"_",P31,"_",E31) -> CL_MLP_PAO_IF_Ortho_25_05_07_Monte-Aranda-84p2-a-82p3 | E31: Monte-Aranda-84p2-a-82p3 | F31: DJI MATRICE 350 RTK | G31: PAO | H31: 45784.167 | I31: 45870 | J31: Activo | K31: =CONCATENATE("https://sig.aminerals.cl/imgdyn/rest/services/CL_MLP_PAO/",U31,"/","ImageServer/file?id=.\",S31,"\",R31,"_",Q31,"_",P31,"\",C31,"&rasterId=") -> https://sig.aminerals.cl/imgdyn/rest/services/CL_MLP_PAO/CL_MLP_PAO_IF_Ortho_ALL/ImageServer/file?id=.\El_Mauro_Puerto_Punta_Chungo_Drone\25_05_07\CL_MLP_PAO_IF_Ortho_25_05_07_Monte-Aranda-84p2-a-82p3.tiff&rasterId= | L31: CL | M31: MLP | N31: IF | O31: Ortho | P31: =TEXT(H31,"dd") -> 07 | Q31: =TEXT(H31,"MM") -> 05 | R31: =TEXT(H31,"YY") -> 25 | S31: El_Mauro_Puerto_Punta_Chungo_Drone | T31: 1 | U31: CL_MLP_PAO_IF_Ortho_ALL | V31: =RIGHT(D31,LEN(D31)-29) -> Monte-Aranda-84p2-a-82p3 | W31: =E31 -> Monte-Aranda-84p2-a-82p3 | X31: =V31=W31 -> TRUE | Y31: =VLOOKUP(D31,'Orden de Imagen'!$A$1:D171,4,FALSE()) -> 020 | Z31: =CONCATENATE(Y31,"_",R31,"_",Q31,"_",P31,"_",E31) -> 020_25_05_07_Monte-Aranda-84p2-a-82p3
A32: 32 | B32: 20250512_Monte-Aranda-84p2-a-82p3-01.tif | C32: CL_MLP_PAO_IF_Ortho_25_05_07_Monte-Aranda-84p2-a-82p3-01.tiff | D32: =CONCATENATE(L32,"_",M32,"_",G32,"_",N32,"_",O32,"_",R32,"_",Q32,"_",P32,"_",E32) -> CL_MLP_PAO_IF_Ortho_25_05_07_Monte-Aranda-84p2-a-82p3-01 | E32: Monte-Aranda-84p2-a-82p3-01 | F32: DJI MATRICE 350 RTK | G32: PAO | H32: 45784.167 | I32: 45870 | J32: Activo | K32: =CONCATENATE("https://sig.aminerals.cl/imgdyn/rest/services/CL_MLP_PAO/",U32,"/","ImageServer/file?id=.\",S32,"\",R32,"_",Q32,"_",P32,"\",C32,"&rasterId=") -> https://sig.aminerals.cl/imgdyn/rest/services/CL_MLP_PAO/CL_MLP_PAO_IF_Ortho_ALL/ImageServer/file?id=.\El_Mauro_Puerto_Punta_Chungo_Drone\25_05_07\CL_MLP_PAO_IF_Ortho_25_05_07_Monte-Aranda-84p2-a-82p3-01.tiff&rasterId= | L32: CL | M32: MLP | N32: IF | O32: Ortho | P32: =TEXT(H32,"dd") -> 07 | Q32: =TEXT(H32,"MM") -> 05 | R32: =TEXT(H32,"YY") -> 25 | S32: El_Mauro_Puerto_Punta_Chungo_Drone | T32: 1 | U32: CL_MLP_PAO_IF_Ortho_ALL | V32: =RIGHT(D32,LEN(D32)-29) -> Monte-Aranda-84p2-a-82p3-01 | W32: =E32 -> Monte-Aranda-84p2-a-82p3-01 | X32: =V32=W32 -> TRUE | Y32: =VLOOKUP(D32,'Orden de Imagen'!$A$1:D173,4,FALSE()) -> #N/A | Z32: =CONCATENATE(Y32,"_",R32,"_",Q32,"_",P32,"_",E32) -> #N/A
A33: 33 | B33: 20250512_Monte-Aranda-84p2-a-82p3-02.tif | C33: CL_MLP_PAO_IF_Ortho_25_05_07_Monte-Aranda-84p2-a-82p3-02.tiff | D33: =CONCATENATE(L33,"_",M33,"_",G33,"_",N33,"_",O33,"_",R33,"_",Q33,"_",P33,"_",E33) -> CL_MLP_PAO_IF_Ortho_25_05_07_Monte-Aranda-84p2-a-82p3-02 | E33: Monte-Aranda-84p2-a-82p3-02 | F33: DJI MATRICE 350 RTK | G33: PAO | H33: 45784.167 | I33: 45870 | J33: Activo | K33: =CONCATENATE("https://sig.aminerals.cl/imgdyn/rest/services/CL_MLP_PAO/",U33,"/","ImageServer/file?id=.\",S33,"\",R33,"_",Q33,"_",P33,"\",C33,"&rasterId=") -> https://sig.aminerals.cl/imgdyn/rest/services/CL_MLP_PAO/CL_MLP_PAO_IF_Ortho_ALL/ImageServer/file?id=.\El_Mauro_Puerto_Punta_Chungo_Drone\25_05_07\CL_MLP_PAO_IF_Ortho_25_05_07_Monte-Aranda-84p2-a-82p3-02.tiff&rasterId= | L33: CL | M33: MLP | N33: IF | O33: Ortho | P33: =TEXT(H33,"dd") -> 07 | Q33: =TEXT(H33,"MM") -> 05 | R33: =TEXT(H33,"YY") -> 25 | S33: El_Mauro_Puerto_Punta_Chungo_Drone | T33: 1 | U33: CL_MLP_PAO_IF_Ortho_ALL | V33: =RIGHT(D33,LEN(D33)-29) -> Monte-Aranda-84p2-a-82p3-02 | W33: =E33 -> Monte-Aranda-84p2-a-82p3-02 | X33: =V33=W33 -> TRUE | Y33: =VLOOKUP(D33,'Orden de Imagen'!$A$1:D174,4,FALSE()) -> #N/A | Z33: =CONCATENATE(Y33,"_",R33,"_",Q33,"_",P33,"_",E33) -> #N/A
A34: 34 | B34: 20250512_Monte-Aranda-84p2-a-82p3-03.tif | C34: CL_MLP_PAO_IF_Ortho_25_05_07_Monte-Aranda-84p2-a-82p3-03.tiff | D34: =CONCATENATE(L34,"_",M34,"_",G34,"_",N34,"_",O34,"_",R34,"_",Q34,"_",P34,"_",E34) -> CL_MLP_PAO_IF_Ortho_25_05_07_Monte-Aranda-84p2-a-82p3-03 | E34: Monte-Aranda-84p2-a-82p3-03 | F34: DJI MATRICE 350 RTK | G34: PAO | H34: 45784.167 | I34: 45870 | J34: Activo | K34: =CONCATENATE("https://sig.aminerals.cl/imgdyn/rest/services/CL_MLP_PAO/",U34,"/","ImageServer/file?id=.\",S34,"\",R34,"_",Q34,"_",P34,"\",C34,"&rasterId=") -> https://sig.aminerals.cl/imgdyn/rest/services/CL_MLP_PAO/CL_MLP_PAO_IF_Ortho_ALL/ImageServer/file?id=.\El_Mauro_Puerto_Punta_Chungo_Drone\25_05_07\CL_MLP_PAO_IF_Ortho_25_05_07_Monte-Aranda-84p2-a-82p3-03.tiff&rasterId= | L34: CL | M34: MLP | N34: IF | O34: Ortho | P34: =TEXT(H34,"dd") -> 07 | Q34: =TEXT(H34,"MM") -> 05 | R34: =TEXT(H34,"YY") -> 25 | S34: El_Mauro_Puerto_Punta_Chungo_Drone | T34: 1 | U34: CL_MLP_PAO_IF_Ortho_ALL | V34: =RIGHT(D34,LEN(D34)-29) -> Monte-Aranda-84p2-a-82p3-03 | W34: =E34 -> Monte-Aranda-84p2-a-82p3-03 | X34: =V34=W34 -> TRUE | Y34: =VLOOKUP(D34,'Orden de Imagen'!$A$1:D175,4,FALSE()) -> #N/A | Z34: =CONCATENATE(Y34,"_",R34,"_",Q34,"_",P34,"_",E34) -> #N/A
A35: 35 | B35: 20250512_Monte-Aranda-84p2-a-82p3-04.tif | C35: CL_MLP_PAO_IF_Ortho_25_05_07_Monte-Aranda-84p2-a-82p3-04.tiff | D35: =CONCATENATE(L35,"_",M35,"_",G35,"_",N35,"_",O35,"_",R35,"_",Q35,"_",P35,"_",E35) -> CL_MLP_PAO_IF_Ortho_25_05_07_Monte-Aranda-84p2-a-82p3-04 | E35: Monte-Aranda-84p2-a-82p3-04 | F35: DJI MATRICE 350 RTK | G35: PAO | H35: 45784.167 | I35: 45870 | J35: Activo | K35: =CONCATENATE("https://sig.aminerals.cl/imgdyn/rest/services/CL_MLP_PAO/",U35,"/","ImageServer/file?id=.\",S35,"\",R35,"_",Q35,"_",P35,"\",C35,"&rasterId=") -> https://sig.aminerals.cl/imgdyn/rest/services/CL_MLP_PAO/CL_MLP_PAO_IF_Ortho_ALL/ImageServer/file?id=.\El_Mauro_Puerto_Punta_Chungo_Drone\25_05_07\CL_MLP_PAO_IF_Ortho_25_05_07_Monte-Aranda-84p2-a-82p3-04.tiff&rasterId= | L35: CL | M35: MLP | N35: IF | O35: Ortho | P35: =TEXT(H35,"dd") -> 07 | Q35: =TEXT(H35,"MM") -> 05 | R35: =TEXT(H35,"YY") -> 25 | S35: El_Mauro_Puerto_Punta_Chungo_Drone | T35: 1 | U35: CL_MLP_PAO_IF_Ortho_ALL | V35: =RIGHT(D35,LEN(D35)-29) -> Monte-Aranda-84p2-a-82p3-04 | W35: =E35 -> Monte-Aranda-84p2-a-82p3-04 | X35: =V35=W35 -> TRUE | Y35: =VLOOKUP(D35,'Orden de Imagen'!$A$1:D176,4,FALSE()) -> #N/A | Z35: =CONCATENATE(Y35,"_",R35,"_",Q35,"_",P35,"_",E35) -> #N/A
A36: 36 | B36: 20250507_Ruta-D-377-E01.tif | C36: CL_MLP_PAO_IF_Ortho_25_05_07_Ruta-D-377-E01.tiff | D36: =CONCATENATE(L36,"_",M36,"_",G36,"_",N36,"_",O36,"_",R36,"_",Q36,"_",P36,"_",E36) -> CL_MLP_PAO_IF_Ortho_25_05_07_Ruta-D-377-E01 | E36: Ruta-D-377-E01 | F36: DJI MATRICE 350 RTK | G36: PAO | H36: 45784.167 | I36: 45870 | J36: Activo | K36: =CONCATENATE("https://sig.aminerals.cl/imgdyn/rest/services/CL_MLP_PAO/",U36,"/","ImageServer/file?id=.\",S36,"\",R36,"_",Q36,"_",P36,"\",C36,"&rasterId=") -> https://sig.aminerals.cl/imgdyn/rest/services/CL_MLP_PAO/CL_MLP_PAO_IF_Ortho_ALL/ImageServer/file?id=.\El_Mauro_Puerto_Punta_Chungo_Drone\25_05_07\CL_MLP_PAO_IF_Ortho_25_05_07_Ruta-D-377-E01.tiff&rasterId= | L36: CL | M36: MLP | N36: IF | O36: Ortho | P36: =TEXT(H36,"dd") -> 07 | Q36: =TEXT(H36,"MM") -> 05 | R36: =TEXT(H36,"YY") -> 25 | S36: El_Mauro_Puerto_Punta_Chungo_Drone | T36: 1 | U36: CL_MLP_PAO_IF_Ortho_ALL | V36: =RIGHT(D36,LEN(D36)-29) -> Ruta-D-377-E01 | W36: =E36 -> Ruta-D-377-E01 | X36: =V36=W36 -> TRUE | Y36: =VLOOKUP(D36,'Orden de Imagen'!$A$1:D177,4,FALSE()) -> #N/A | Z36: =CONCATENATE(Y36,"_",R36,"_",Q36,"_",P36,"_",E36) -> #N/A
A37: 37 | B37: 20250507_Ruta-D-377-E02.tif | C37: CL_MLP_PAO_IF_Ortho_25_05_07_Ruta-D-377-E02.tiff | D37: =CONCATENATE(L37,"_",M37,"_",G37,"_",N37,"_",O37,"_",R37,"_",Q37,"_",P37,"_",E37) -> CL_MLP_PAO_IF_Ortho_25_05_07_Ruta-D-377-E02 | E37: Ruta-D-377-E02 | F37: DJI MATRICE 350 RTK | G37: PAO | H37: 45784.167 | I37: 45870 | J37: Activo | K37: =CONCATENATE("https://sig.aminerals.cl/imgdyn/rest/services/CL_MLP_PAO/",U37,"/","ImageServer/file?id=.\",S37,"\",R37,"_",Q37,"_",P37,"\",C37,"&rasterId=") -> https://sig.aminerals.cl/imgdyn/rest/services/CL_MLP_PAO/CL_MLP_PAO_IF_Ortho_ALL/ImageServer/file?id=.\El_Mauro_Puerto_Punta_Chungo_Drone\25_05_07\CL_MLP_PAO_IF_Ortho_25_05_07_Ruta-D-377-E02.tiff&rasterId= | L37: CL | M37: MLP | N37: IF | O37: Ortho | P37: =TEXT(H37,"dd") -> 07 | Q37: =TEXT(H37,"MM") -> 05 | R37: =TEXT(H37,"YY") -> 25 | S37: El_Mauro_Puerto_Punta_Chungo_Drone | T37: 1 | U37: CL_MLP_PAO_IF_Ortho_ALL | V37: =RIGHT(D37,LEN(D37)-29) -> Ruta-D-377-E02 | W37: =E37 -> Ruta-D-377-E02 | X37: =V37=W37 -> TRUE | Y37: =VLOOKUP(D37,'Orden de Imagen'!$A$1:D178,4,FALSE()) -> #N/A | Z37: =CONCATENATE(Y37,"_",R37,"_",Q37,"_",P37,"_",E37) -> #N/A
A38: 38 | B38: 20250507_Ruta-D-377-E03.tif | C38: CL_MLP_PAO_IF_Ortho_25_05_07_Ruta-D-377-E03.tiff | D38: =CONCATENATE(L38,"_",M38,"_",G38,"_",N38,"_",O38,"_",R38,"_",Q38,"_",P38,"_",E38) -> CL_MLP_PAO_IF_Ortho_25_05_07_Ruta-D-377-E03 | E38: Ruta-D-377-E03 | F38: DJI MATRICE 350 RTK | G38: PAO | H38: 45784.167 | I38: 45870 | J38: Activo | K38: =CONCATENATE("https://sig.aminerals.cl/imgdyn/rest/services/CL_MLP_PAO/",U38,"/","ImageServer/file?id=.\",S38,"\",R38,"_",Q38,"_",P38,"\",C38,"&rasterId=") -> https://sig.aminerals.cl/imgdyn/rest/services/CL_MLP_PAO/CL_MLP_PAO_IF_Ortho_ALL/ImageServer/file?id=.\El_Mauro_Puerto_Punta_Chungo_Drone\25_05_07\CL_MLP_PAO_IF_Ortho_25_05_07_Ruta-D-377-E03.tiff&rasterId= | L38: CL | M38: MLP | N38: IF | O38: Ortho | P38: =TEXT(H38,"dd") -> 07 | Q38: =TEXT(H38,"MM") -> 05 | R38: =TEXT(H38,"YY") -> 25 | S38: El_Mauro_Puerto_Punta_Chungo_Drone | T38: 1 | U38: CL_MLP_PAO_IF_Ortho_ALL | V38: =RIGHT(D38,LEN(D38)-29) -> Ruta-D-377-E03 | W38: =E38 -> Ruta-D-377-E03 | X38: =V38=W38 -> TRUE | Y38: =VLOOKUP(D38,'Orden de Imagen'!$A$1:D179,4,FALSE()) -> #N/A | Z38: =CONCATENATE(Y38,"_",R38,"_",Q38,"_",P38,"_",E38) -> #N/A
A39: 39 | C39: =CONCATENATE(L39,"_",M39,"_",G39,"_",N39,"_",O39,"_",R39,"_",Q39,"_",P39,"_",E39,".tiff") -> CL_MLP_PAO_IF_Ortho_25_05_12_EDT.tiff | D39: =CONCATENATE(L39,"_",M39,"_",G39,"_",N39,"_",O39,"_",R39,"_",Q39,"_",P39,"_",E39) -> CL_MLP_PAO_IF_Ortho_25_05_12_EDT | E39: EDT | F39: DJI MATRICE 350 RTK | G39: PAO | H39: 45789.167 | I39: 45870 | J39: Activo | K39: =CONCATENATE("https://sig.aminerals.cl/imgdyn/rest/services/CL_MLP_PAO/",U39,"/","ImageServer/file?id=.\",S39,"\",R39,"_",Q39,"_",P39,"\",C39,"&rasterId=") -> https://sig.aminerals.cl/imgdyn/rest/services/CL_MLP_PAO/CL_MLP_PAO_IF_Ortho_ALL/ImageServer/file?id=.\Puerto_Punta_Chungo_Drone\25_05_12\CL_MLP_PAO_IF_Ortho_25_05_12_EDT.tiff&rasterId= | L39: CL | M39: MLP | N39: IF | O39: Ortho | P39: =TEXT(H39,"dd") -> 12 | Q39: =TEXT(H39,"MM") -> 05 | R39: =TEXT(H39,"YY") -> 25 | S39: Puerto_Punta_Chungo_Drone | T39: 1 | U39: CL_MLP_PAO_IF_Ortho_ALL | V39: =RIGHT(D39,LEN(D39)-29) -> EDT | W39: =E39 -> EDT | X39: =V39=W39 -> TRUE | Y39: =VLOOKUP(D39,'Orden de Imagen'!$A$1:D180,4,FALSE()) -> 021 | Z39: =CONCATENATE(Y39,"_",R39,"_",Q39,"_",P39,"_",E39) -> 021_25_05_12_EDT
A40: 41 | B40: 20250512_EDT-Completa-01.tiff | C40: CL_MLP_PAO_IF_Ortho_25_05_12_EDT-Completa-01.tif | D40: =CONCATENATE(L40,"_",M40,"_",G40,"_",N40,"_",O40,"_",R40,"_",Q40,"_",P40,"_",E40) -> CL_MLP_PAO_IF_Ortho_25_05_12_EDT-Completa-01 | E40: EDT-Completa-01 | F40: DJI MATRICE 350 RTK | G40: PAO | H40: 45789.167 | I40: 45870 | J40: Activo | K40: =CONCATENATE("https://sig.aminerals.cl/imgdyn/rest/services/CL_MLP_PAO/",U40,"/","ImageServer/file?id=.\",S40,"\",R40,"_",Q40,"_",P40,"\",C40,"&rasterId=") -> https://sig.aminerals.cl/imgdyn/rest/services/CL_MLP_PAO/CL_MLP_PAO_IF_Ortho_ALL/ImageServer/file?id=.\Puerto_Punta_Chungo_Drone\25_05_12\CL_MLP_PAO_IF_Ortho_25_05_12_EDT-Completa-01.tif&rasterId= | L40: CL | M40: MLP | N40: IF | O40: Ortho | P40: =TEXT(H40,"dd") -> 12 | Q40: =TEXT(H40,"MM") -> 05 | R40: =TEXT(H40,"YY") -> 25 | S40: Puerto_Punta_Chungo_Drone | T40: 1 | U40: CL_MLP_PAO_IF_Ortho_ALL | V40: =RIGHT(D40,LEN(D40)-29) -> EDT-Completa-01 | W40: =E40 -> EDT-Completa-01 | X40: =V40=W40 -> TRUE | Y40: =VLOOKUP(D40,'Orden de Imagen'!$A$1:D182,4,FALSE()) -> #N/A | Z40: =CONCATENATE(Y40,"_",R40,"_",Q40,"_",P40,"_",E40) -> #N/A
...

Sheet Hoja1
A1: Fecha
A2: CL_MLP_PAO_IF_Ortho_26_04_29_TORRE_E85_A_E_125
A3: CL_MLP_PAO_IF_Ortho_26_04_30_EM4
A4: CL_MLP_PAO_IF_Ortho_26_04_30_TORRES_E35_A_E48
A5: CL_MLP_PAO_IF_Ortho_26_05_01_Acceso_a_pozos
A6: CL_MLP_PAO_IF_Ortho_26_05_01_EM1
A7: CL_MLP_PAO_IF_Ortho_26_05_01_EV1
A8: CL_MLP_PAO_IF_Ortho_26_05_01_Pozos_PRP
A9: CL_MLP_PAO_IF_Ortho_26_05_02_ED1
A10: CL_MLP_PAO_IF_Ortho_26_05_02_EM2
A11: CL_MLP_PAO_IF_Ortho_26_05_02_EM2_S2
A12: CL_MLP_PAO_IF_Ortho_26_05_02_EV2
... A36: CL_MLP_PAO_IF_Ortho_26_05_09_EV2

Sheet Orden de Imagen
A1: Name | B1: NombreVuelo | C1: Numero | D1: 0
A2: CL_MLP_PAO_IF_Ortho_25_01_08_EB1 | B2: =RIGHT(A2, LEN(A2)-29) -> EB1 | C2: 1 | D2: =CONCATENATE("00",C2) -> 001
A3: CL_MLP_PAO_IF_Ortho_25_02_26_RutaD835 | B3: =RIGHT(A3, LEN(A3)-29) -> RutaD835 | C3: 2 | D3: =CONCATENATE("00",C3) -> 002 | E3: =C3-C2 -> 1
A4: CL_MLP_PAO_IF_Ortho_25_03_10_NSTC_116a118 | B4: =RIGHT(A4, LEN(A4)-29) -> NSTC_116a118 | C4: 3 | D4: =CONCATENATE("00",C4) -> 003 | E4: =C4-C3 -> 1
A5: CL_MLP_PAO_IF_Ortho_25_03_10_NSTC_118a120 | B5: =RIGHT(A5, LEN(A5)-29) -> NSTC_118a120 | C5: 4 | D5: =CONCATENATE("00",C5) -> 004 | E5: =C5-C4 -> 1
A6: CL_MLP_PAO_IF_Ortho_25_03_12_SRA2 | B6: =RIGHT(A6, LEN(A6)-29) -> SRA2 | C6: 5 | D6: =CONCATENATE("00",C6) -> 005 | E6: =C6-C5 -> 1
A7: CL_MLP_PAO_IF_Ortho_25_03_17_NSTC_Km_120_a_121 | B7: =RIGHT(A7, LEN(A7)-29) -> NSTC_Km_120_a_121 | C7: 6 | D7: =CONCATENATE("00",C7) -> 006 | E7: =C7-C6 -> 1
A8: CL_MLP_PAO_IF_Ortho_25_03_19_Orejas16_Ruta-D-865 | B8: =RIGHT(A8, LEN(A8)-29) -> Orejas16_Ruta-D-865 | C8: 7 | D8: =CONCATENATE("00",C8) -> 007 | E8: =C8-C7 -> 1
A9: CL_MLP_PAO_IF_Ortho_25_03_19_Orejas17_Ruta-D-865 | B9: =RIGHT(A9, LEN(A9)-29) -> Orejas17_Ruta-D-865 | C9: 8 | D9: =CONCATENATE("00",C9) -> 008 | E9: =C9-C8 -> 1
A10: CL_MLP_PAO_IF_Ortho_25_03_19_Orejas18 | B10: =RIGHT(A10, LEN(A10)-29) -> Orejas18 | C10: 9 | D10: =CONCATENATE("00",C10) -> 009 | E10: =C10-C9 -> 1
A11: CL_MLP_PAO_IF_Ortho_25_03_31_EB2 | B11: =RIGHT(A11, LEN(A11)-29) -> EB2 | C11: 10 | D11: =CONCATENATE("0",C11) -> 010 | E11: =C11-C10 -> 1
A12: CL_MLP_PAO_IF_Ortho_25_03_31_EV2 | B12: =RIGHT(A12, LEN(A12)-29) -> EV2 | C12: 11 | D12: =CONCATENATE("0",C12) -> 011 | E12: =C12-C11 -> 1
A13: CL_MLP_PAO_IF_Ortho_25_04_02_DME-13 | B13: =RIGHT(A13, LEN(A13)-29) -> DME-13 | C13: 12 | D13: =CONCATENATE("0",C13) -> 012 | E13: =C13-C12 -> 1
A14: CL_MLP_PAO_IF_Ortho_25_04_02_Patio-Acopio-17 | B14: =RIGHT(A14, LEN(A14)-29) -> Patio-Acopio-17 | C14: 13 | D14: =CONCATENATE("0",C14) -> 013 | E14: =C14-C13 -> 1
A15: CL_MLP_PAO_IF_Ortho_25_04_02_Ruta-SE-a-DME-13 | B15: =RIGHT(A15, LEN(A15)-29) -> Ruta-SE-a-DME-13 | C15: 14 | D15: =CONCATENATE("0",C15) -> 014 | E15: =C15-C14 -> 1
A16: CL_MLP_PAO_IF_Ortho_25_04_03_Area-patio-19b-y-armado | B16: =RIGHT(A16, LEN(A16)-29) -> Area-patio-19b-y-armado | C16: 15 | D16: =CONCATENATE("0",C16) -> 015 | E16: =C16-C15 -> 1
A17: CL_MLP_PAO_IF_Ortho_25_04_03_Subestacion-El-Mauro | B17: =RIGHT(A17, LEN(A17)-29) -> Subestacion-El-Mauro | C17: 16 | D17: =CONCATENATE("0",C17) -> 016 | E17: =C17-C16 -> 1
A18: CL_MLP_PAO_IF_Ortho_25_04_09_Cachimba_de_Bajo_Camisas_ED2 | B18: =RIGHT(A18, LEN(A18)-29) -> Cachimba_de_Bajo_Camisas_ED2 | C18: 17 | D18: =CONCATENATE("0",C18) -> 017 | E18: =C18-C17 -> 1
A19: CL_MLP_PAO_IF_Ortho_25_04_10_Sector_Pupio_I_Area_1 | B19: =RIGHT(A19, LEN(A19)-29) -> Sector_Pupio_I_Area_1 | C19: 18 | D19: =CONCATENATE("0",C19) -> 018 | E19: =C19-C18 -> 1
A20: CL_MLP_PAO_IF_Ortho_25_05_07_Monte_Aranda_82p3_a_80p7 | B20: =RIGHT(A20, LEN(A20)-29) -> Monte_Aranda_82p3_a_80p7 | C20: 19 | D20: =CONCATENATE("0",C20) -> 019 | E20: =C20-C19 -> 1
A21: CL_MLP_PAO_IF_Ortho_25_05_07_Monte-Aranda-84p2-a-82p3 | B21: =RIGHT(A21, LEN(A21)-29) -> Monte-Aranda-84p2-a-82p3 | C21: 20 | D21: =CONCATENATE("0",C21) -> 020 | E21: =C21-C20 -> 1
A22: CL_MLP_PAO_IF_Ortho_25_05_12_EDT | B22: =RIGHT(A22, LEN(A22)-29) -> EDT | C22: 21 | D22: =CONCATENATE("0",C22) -> 021 | E22: =C22-C21 -> 1
... A100: CL_MLP_PAO_IF_Ortho_25_09_25_EM1 | B100: =RIGHT(A100, LEN(A100)-29) -> EM1 | C100: 99 | D100: =CONCATENATE("0",C100) -> 099 | E100: =C100-C99 -> 1
A101: CL_MLP_PAO_IF_Ortho_25_09_25_EM1-EstacionChoapa3 | B101: =RIGHT(A101, LEN(A101)-29) -> EM1-EstacionChoapa3 | C101: 100 | D101: =C101 -> 100 | E101: =C101-C100 -> 1
A102: CL_MLP_PAO_IF_Ortho_25_09_25_NSTC-km-7p0-a-8p3 | B102: =RIGHT(A102, LEN(A102)-29) -> NSTC-km-7p0-a-8p3 | C102: 101 | D102: =C102 -> 101 | E102: =C102-C101 -> 1
A103: CL_MLP_PAO_IF_Ortho_25_09_25_SRA-2-53p2-a-54p6 | B103: =RIGHT(A103, LEN(A103)-29) -> SRA-2-53p2-a-54p6 | C103: 102 | D103: =C103 -> 102 | E103: =C103-C102 -> 1
A104: CL_MLP_PAO_IF_Ortho_25_10_01_NSTC_Km_87p1_a_88p7 | B104: =RIGHT(A104, LEN(A104)-29) -> NSTC_Km_87p1_a_88p7 | C104: 103 | D104: =C104 -> 103 | E104: =C104-C103 -> 1
A105: CL_MLP_PAO_IF_Ortho_25_10_01_Pupio_I_sector_2_2 | B105: =RIGHT(A105, LEN(A105)-29) -> Pupio_I_sector_2_2 | C105: 104 | D105: =C105 -> 104 | E105: =C105-C104 -> 1
A106: CL_MLP_PAO_IF_Ortho_25_10_02_NSTC_Km_91p5_a_92 | B106: =RIGHT(A106, LEN(A106)-29) -> NSTC_Km_91p5_a_92 | C106: 105 | D106: =C106 -> 105 | E106: =C106-C105 -> 1
A107: CL_MLP_PAO_IF_Ortho_25_10_02_NSTC_Km_92_a_93 | B107: =RIGHT(A107, LEN(A107)-29) -> NSTC_Km_92_a_93 | C107: 106 | D107: =C107 -> 106 | E107: =C107-C106 -> 1
A108: CL_MLP_PAO_IF_Ortho_25_10_02_NSTC_Km_93_a_94 | B108: =RIGHT(A108, LEN(A108)-29) -> NSTC_Km_93_a_94 | C108: 107 | D108: =C108 -> 107 | E108: =C108-C107 -> 1
A109: CL_MLP_PAO_IF_Ortho_25_10_02_NSTC_Km_94_a_95 | B109: =RIGHT(A109, LEN(A109)-29) -> NSTC_Km_94_a_95 | C109: 108 | D109: =C109 -> 108 | E109: =C109-C108 -> 1
A110: CL_MLP_PAO_IF_Ortho_25_10_07_DME5A_DME17_a_NSTC_78p9 | B110: =RIGHT(A110, LEN(A110)-29) -> DME5A_DME17_a_NSTC_78p9 | C110: 109 | D110: =C110 -> 109 | E110: =C110-C109 -> 1
A111: CL_MLP_PAO_IF_Ortho_25_10_07_DME5C_DME_16_a_NSTC_79p4 | B111: =RIGHT(A111, LEN(A111)-29) -> DME5C_DME_16_a_NSTC_79p4 | C111: 110 | D111: =C111 -> 110 | E111: =C111-C110 -> 1
A112: CL_MLP_PAO_IF_Ortho_25_10_08_ElMauro_E7_E9 | B112: =RIGHT(A112, LEN(A112)-29) -> ElMauro_E7_E9 | C112: 111 | D112: =C112 -> 111 | E112: =C112-C111 -> 1
... A460: CL_MLP_PAO_IF_Ortho_26_05_09_EV2 | B460: =RIGHT(A460, LEN(A460)-29) -> EV2 | C460: 457 | D460: =C460 -> 457 | E460: =C460-C459 -> 1

Sheet URL PARA REFERIDO
A1: OBJECTID * | B1: Shape * | C1: Name | D1: MinPS | E1: MaxPS | F1: LowPS | G1: HighPS | H1: Category | I1: Tag | J1: GroupName | K1: ProductNam | L1: CenterX | M1: CenterY | N1: ZOrder | O1: TypeID | P1: ItemTS | Q1: UriHash | R1: Sector | S1: Sensor | T1: Proyecto | U1: Fecha_Adqu | V1: Fecha_Publ | W1: Estado | X1: URL | Y1: ID IMAGE SERVER | Z1: URL FINAL
A2: 1 | B2: Polygon | C2: CL_MLP_PAO_IF_Ortho_25_02_01_Transversal_TR_0 | D2: 0 | E2: 1.2 | F2: 0.1 | G2: 0.2 | H2: 1 | I2: Dataset | L2: 349592.8 | M2: 6479583.7 | N2: 0 | O2: 12 | P2: 45901.769 | Q2: 3F6B9CAB6EAF6ACEFAE1DCA5B2D14BC4 | R2: Sector 0 | S2: Vuelo Aerofotogramétrico | T2: PAO | U2: <Null> | V2: <Null> | W2: Activo | X2: https://sig.aminerals.cl/imgdyn/rest/services/CL_MLP_PAO/CL_MLP_PAO_IF_Ortho_Transversal/ImageServer/file?id=.%5CTransversal_Aereo%5C25_02_02%5CCL_MLP_PAO_IF_Ortho_25_02_01_Transversal_TR_1.tif | Y2: =VLOOKUP(C2,$A$418:$B$538,2,FALSE()) -> 9803 | Z2: =CONCATENATE(X2,"&rasterId=",Y2) -> https://sig.aminerals.cl/imgdyn/rest/services/CL_MLP_PAO/CL_MLP_PAO_IF_Ortho_Transversal/ImageServer/file?id=.%5CTransversal_Aereo%5C25_02_02%5CCL_MLP_PAO_IF_Ortho_25_02_01_Transversal_TR_1.tif&rasterId=9803
A3: 2 | B3: Polygon | C3: CL_MLP_PAO_IF_Ortho_25_02_01_Transversal_TR_1 | D3: 0 | E3: 1.2 | F3: 0.1 | G3: 0.4 | H3: 1 | I3: Dataset | L3: 347218.5 | M3: 6476631 | N3: 0 | O3: 12 | P3: 45901.769 | Q3: C74D29FB11693EC647FF15DB4FEFA53E | R3: Sector 1 | S3: Vuelo Aerofotogramétrico | T3: PAO | U3: <Null> | V3: <Null> | W3: Activo | X3: https://sig.aminerals.cl/imgdyn/rest/services/CL_MLP_PAO/CL_MLP_PAO_IF_Ortho_Transversal/ImageServer/file?id=.%5CTransversal_Aereo%5C25_02_02%5CCL_MLP_PAO_IF_Ortho_25_02_01_Transversal_TR_1.tif | Y3: =VLOOKUP(C3,$A$418:$B$538,2,FALSE()) -> 9804 | Z3: =CONCATENATE(X3,"&rasterId=",Y3) -> https://sig.aminerals.cl/imgdyn/rest/services/CL_MLP_PAO/CL_MLP_PAO_IF_Ortho_Transversal/ImageServer/file?id=.%5CTransversal_Aereo%5C25_02_02%5CCL_MLP_PAO_IF_Ortho_25_02_01_Transversal_TR_1.tif&rasterId=9804
A4: 3 | B4: Polygon | C4: CL_MLP_PAO_IF_Ortho_25_02_01_Transversal_TR_10 | D4: 0 | E4: 1.2 | F4: 0.1 | G4: 0.4 | H4: 1 | I4: Dataset | L4: 273959.02 | M4: 6471800.4 | N4: 0 | O4: 12 | P4: 45901.769 | Q4: E657F485B42BB4665ACF912FB213C8CD | R4: Sector 10 | S4: Vuelo Aerofotogramétrico | T4: PAO | U4: <Null> | V4: <Null> | W4: Activo | X4: https://sig.aminerals.cl/imgdyn/rest/services/CL_MLP_PAO/CL_MLP_PAO_IF_Ortho_Transversal/ImageServer/file?id=.%5CTransversal_Aereo%5C25_02_02%5CCL_MLP_PAO_IF_Ortho_25_02_01_Transversal_TR_10.tif | Y4: =VLOOKUP(C4,$A$418:$B$538,2,FALSE()) -> 9805 | Z4: =CONCATENATE(X4,"&rasterId=",Y4) -> https://sig.aminerals.cl/imgdyn/rest/services/CL_MLP_PAO/CL_MLP_PAO_IF_Ortho_Transversal/ImageServer/file?id=.%5CTransversal_Aereo%5C25_02_02%5CCL_MLP_PAO_IF_Ortho_25_02_01_Transversal_TR_10.tif&rasterId=9805
A5: 4 | B5: Polygon | C5: CL_MLP_PAO_IF_Ortho_25_02_01_Transversal_TR_100 | D5: 0 | E5: 1.2 | F5: 0.1 | G5: 0.2 | H5: 1 | I5: Dataset | L5: 297858.12 | M5: 6461838.3 | N5: 0 | O5: 12 | P5: 45901.769 | Q5: 85C0DF7175A722966D6838798E475004 | R5: Sector 100 | S5: Vuelo Aerofotogramétrico | T5: PAO | U5: <Null> | V5: <Null> | W5: Activo | X5: https://sig.aminerals.cl/imgdyn/rest/services/CL_MLP_PAO/CL_MLP_PAO_IF_Ortho_Transversal/ImageServer/file?id=.%5CTransversal_Aereo%5C25_02_02%5CCL_MLP_PAO_IF_Ortho_25_02_01_Transversal_TR_100.tif | Y5: =VLOOKUP(C5,$A$418:$B$538,2,FALSE()) -> 9806 | Z5: =CONCATENATE(X5,"&rasterId=",Y5) -> https://sig.aminerals.cl/imgdyn/rest/services/CL_MLP_PAO/CL_MLP_PAO_IF_Ortho_Transversal/ImageServer/file?id=.%5CTransversal_Aereo%5C25_02_02%5CCL_MLP_PAO_IF_Ortho_25_02_01_Transversal_TR_100.tif&rasterId=9806
A6: 5 | B6: Polygon | C6: CL_MLP_PAO_IF_Ortho_25_02_01_Transversal_TR_101 | D6: 0 | E6: 1.2 | F6: 0.1 | G6: 0.4 | H6: 1 | I6: Dataset | L6: 296914.78 | M6: 6462010.5 | N6: 0 | O6: 12 | P6: 45901.769 | Q6: EFE7C00140CEE9BADE371A68DFFA579D | R6: Sector 101 | S6: Vuelo Aerofotogramétrico | T6: PAO | U6: <Null> | V6: <Null> | W6: Activo | X6: https://sig.aminerals.cl/imgdyn/rest/services/CL_MLP_PAO/CL_MLP_PAO_IF_Ortho_Transversal/ImageServer/file?id=.%5CTransversal_Aereo%5C25_02_02%5CCL_MLP_PAO_IF_Ortho_25_02_01_Transversal_TR_101.tif | Y6: =VLOOKUP(C6,$A$418:$B$538,2,FALSE()) -> 9807 | Z6: =CONCATENATE(X6,"&rasterId=",Y6) -> https://sig.aminerals.cl/imgdyn/rest/services/CL_MLP_PAO/CL_MLP_PAO_IF_Ortho_Transversal/ImageServer/file?id=.%5CTransversal_Aereo%5C25_02_02%5CCL_MLP_PAO_IF_Ortho_25_02_01_Transversal_TR_101.tif&rasterId=9807
A7: 6 | B7: Polygon | C7: CL_MLP_PAO_IF_Ortho_25_02_01_Transversal_TR_102 | D7: 0 | E7: 1.2 | F7: 0.1 | G7: 0.2 | H7: 1 | I7: Dataset | L7: 296144.52 | M7: 6462264.9 | N7: 0 | O7: 12 | P7: 45901.769 | Q7: C1F1EB4796DF99D46B9ECB182969F69C | R7: Sector 102 | S7: Vuelo Aerofotogramétrico | T7: PAO | U7: <Null> | V7: <Null> | W7: Activo | X7: https://sig.aminerals.cl/imgdyn/rest/services/CL_MLP_PAO/CL_MLP_PAO_IF_Ortho_Transversal/ImageServer/file?id=.%5CTransversal_Aereo%5C25_02_02%5CCL_MLP_PAO_IF_Ortho_25_02_01_Transversal_TR_102.tif | Y7: =VLOOKUP(C7,$A$418:$B$538,2,FALSE()) -> 9808 | Z7: =CONCATENATE(X7,"&rasterId=",Y7) -> https://sig.aminerals.cl/imgdyn/rest/services/CL_MLP_PAO/CL_MLP_PAO_IF_Ortho_Transversal/ImageServer/file?id=.%5CTransversal_Aereo%5C25_02_02%5CCL_MLP_PAO_IF_Ortho_25_02_01_Transversal_TR_102.tif&rasterId=9808
A8: 7 | B8: Polygon | C8: CL_MLP_PAO_IF_Ortho_25_02_01_Transversal_TR_103 | D8: 0 | E8: 1.2 | F8: 0.1 | G8: 0.2 | H8: 1 | I8: Dataset | L8: 296063.31 | M8: 6463101.4 | N8: 0 | O8: 12 | P8: 45901.769 | Q8: CA18D1996DFC4C1EAD856C9023578878 | R8: Sector 103 | S8: Vuelo Aerofotogramétrico | T8: PAO | U8: <Null> | V8: <Null> | W8: Activo | X8: https://sig.aminerals.cl/imgdyn/rest/services/CL_MLP_PAO/CL_MLP_PAO_IF_Ortho_Transversal/ImageServer/file?id=.%5CTransversal_Aereo%5C25_02_02%5CCL_MLP_PAO_IF_Ortho_25_02_01_Transversal_TR_103.tif | Y8: =VLOOKUP(C8,$A$418:$B$538,2,FALSE()) -> 9809 | Z8: =CONCATENATE(X8,"&rasterId=",Y8) -> https://sig.aminerals.cl/imgdyn/rest/services/CL_MLP_PAO/CL_MLP_PAO_IF_Ortho_Transversal/ImageServer/file?id=.%5CTransversal_Aereo%5C25_02_02%5CCL_MLP_PAO_IF_Ortho_25_02_01_Transversal_TR_103.tif&rasterId=9809
A9: 8 | B9: Polygon | C9: CL_MLP_PAO_IF_Ortho_25_02_01_Transversal_TR_104 | D9: 0 | E9: 1.2 | F9: 0.1 | G9: 0.4 | H9: 1 | I9: Dataset | L9: 295886.15 | M9: 6464088.1 | N9: 0 | O9: 12 | P9: 45901.769 | Q9: 7946903D82566728D08CE79538EA96C5 | R9: Sector 104 | S9: Vuelo Aerofotogramétrico | T9: PAO | U9: <Null> | V9: <Null> | W9: Activo | X9: https://sig.aminerals.cl/imgdyn/rest/services/CL_MLP_PAO/CL_MLP_PAO_IF_Ortho_Transversal/ImageServer/file?id=.%5CTransversal_Aereo%5C25_02_02%5CCL_MLP_PAO_IF_Ortho_25_02_01_Transversal_TR_104.tif | Y9: =VLOOKUP(C9,$A$418:$B$538,2,FALSE()) -> 9810 | Z9: =CONCATENATE(X9,"&rasterId=",Y9) -> https://sig.aminerals.cl/imgdyn/rest/services/CL_MLP_PAO/CL_MLP_PAO_IF_Ortho_Transversal/ImageServer/file?id=.%5CTransversal_Aereo%5C25_02_02%5CCL_MLP_PAO_IF_Ortho_25_02_01_Transversal_TR_104.tif&rasterId=9810
